<?xml version="1.0" encoding="UTF-8"?>
<robot generator="Robot 4.1.1 (Python 3.10.11 on win32)" generated="20230806 21:12:08.426" rpa="false" schemaversion="2">
<suite id="s1" name="Functional Tests" source="C:\Users\piyat\source\repos\Demo_API_AutomationTest_RobotFramwork\testcases\functional_tests">
<suite id="s1-s1" name="getUser" source="C:\Users\piyat\source\repos\Demo_API_AutomationTest_RobotFramwork\testcases\functional_tests\getUser.robot">
<test id="s1-s1-t1" name="Get user - Validate user Id">
<kw name="Set Test Variable" library="BuiltIn">
<arg>${id}</arg>
<arg>${userdata.userId}</arg>
<doc>Makes a variable available everywhere within the scope of the current test.</doc>
<msg timestamp="20230806 21:12:08.793" level="INFO">${id} = 2,</msg>
<status status="PASS" starttime="20230806 21:12:08.792" endtime="20230806 21:12:08.794"/>
</kw>
<kw name="Set Test Variable" library="BuiltIn">
<arg>${email}</arg>
<arg>${userdata.email}</arg>
<doc>Makes a variable available everywhere within the scope of the current test.</doc>
<msg timestamp="20230806 21:12:08.795" level="INFO">${email} = janet.weaver@reqres.in,</msg>
<status status="PASS" starttime="20230806 21:12:08.794" endtime="20230806 21:12:08.795"/>
</kw>
<kw name="Set Test Variable" library="BuiltIn">
<arg>${firstname}</arg>
<arg>${userdata.first_name}</arg>
<doc>Makes a variable available everywhere within the scope of the current test.</doc>
<msg timestamp="20230806 21:12:08.799" level="INFO">${firstname} = Janet,</msg>
<status status="PASS" starttime="20230806 21:12:08.797" endtime="20230806 21:12:08.799"/>
</kw>
<kw name="Set Test Variable" library="BuiltIn">
<arg>${lastname}</arg>
<arg>${userdata.last_name}</arg>
<doc>Makes a variable available everywhere within the scope of the current test.</doc>
<msg timestamp="20230806 21:12:08.801" level="INFO">${lastname} = Weaver,</msg>
<status status="PASS" starttime="20230806 21:12:08.800" endtime="20230806 21:12:08.801"/>
</kw>
<tag>demo</tag>
<tag>getuser</tag>
<status status="PASS" starttime="20230806 21:12:08.791" endtime="20230806 21:12:08.802"/>
</test>
<test id="s1-s1-t2" name="Get user - Invalidate user Id">
<kw name="Set Test Variable" library="BuiltIn">
<arg>${id}</arg>
<arg>${userdata.userId}</arg>
<doc>Makes a variable available everywhere within the scope of the current test.</doc>
<msg timestamp="20230806 21:12:08.805" level="INFO">${id} = 2,</msg>
<status status="PASS" starttime="20230806 21:12:08.804" endtime="20230806 21:12:08.805"/>
</kw>
<tag>demo</tag>
<tag>getuser</tag>
<status status="PASS" starttime="20230806 21:12:08.803" endtime="20230806 21:12:08.806"/>
</test>
<status status="PASS" starttime="20230806 21:12:08.446" endtime="20230806 21:12:08.808"/>
</suite>
<suite id="s1-s2" name="Login" source="C:\Users\piyat\source\repos\Demo_API_AutomationTest_RobotFramwork\testcases\functional_tests\login.robot">
<test id="s1-s2-t1" name="Verify that users cann't login when email or password are incorrect via api">
<kw name="Set Test Variable" library="BuiltIn">
<arg>${email}</arg>
<arg>${authentication.email}</arg>
<doc>Makes a variable available everywhere within the scope of the current test.</doc>
<msg timestamp="20230806 21:12:08.919" level="INFO">${email} = eve.holt@reqres.in,</msg>
<status status="PASS" starttime="20230806 21:12:08.918" endtime="20230806 21:12:08.919"/>
</kw>
<kw name="Set Test Variable" library="BuiltIn">
<arg>${password}</arg>
<arg>${authentication.incorrect_password}</arg>
<doc>Makes a variable available everywhere within the scope of the current test.</doc>
<msg timestamp="20230806 21:12:08.922" level="FAIL">Resolving variable '${authentication.incorrect_password}' failed: AttributeError: incorrect_password</msg>
<status status="FAIL" starttime="20230806 21:12:08.920" endtime="20230806 21:12:08.922"/>
</kw>
<tag>demo</tag>
<tag>regression</tag>
<status status="FAIL" starttime="20230806 21:12:08.917" endtime="20230806 21:12:08.922">Resolving variable '${authentication.incorrect_password}' failed: AttributeError: incorrect_password</status>
</test>
<status status="FAIL" starttime="20230806 21:12:08.810" endtime="20230806 21:12:08.924"/>
</suite>
<suite id="s1-s3" name="updateUser" source="C:\Users\piyat\source\repos\Demo_API_AutomationTest_RobotFramwork\testcases\functional_tests\updateUser.robot">
<test id="s1-s3-t1" name="Update User - Valid User ID">
<kw name="Set Test Variable" library="BuiltIn">
<arg>${name}</arg>
<arg>${updatedata.name}</arg>
<doc>Makes a variable available everywhere within the scope of the current test.</doc>
<msg timestamp="20230806 21:12:09.037" level="INFO">${name} = morpheus</msg>
<status status="PASS" starttime="20230806 21:12:09.035" endtime="20230806 21:12:09.037"/>
</kw>
<kw name="Set Test Variable" library="BuiltIn">
<arg>${job}</arg>
<arg>${updatedata.job}</arg>
<doc>Makes a variable available everywhere within the scope of the current test.</doc>
<msg timestamp="20230806 21:12:09.040" level="INFO">${job} = zion resident</msg>
<status status="PASS" starttime="20230806 21:12:09.037" endtime="20230806 21:12:09.040"/>
</kw>
<kw name="Set Test Variable" library="BuiltIn">
<arg>${id}</arg>
<arg>${userdata.userId}</arg>
<doc>Makes a variable available everywhere within the scope of the current test.</doc>
<msg timestamp="20230806 21:12:09.043" level="INFO">${id} = 2,</msg>
<status status="PASS" starttime="20230806 21:12:09.041" endtime="20230806 21:12:09.043"/>
</kw>
<tag>demo</tag>
<tag>updateUser</tag>
<status status="PASS" starttime="20230806 21:12:09.034" endtime="20230806 21:12:09.044"/>
</test>
<status status="PASS" starttime="20230806 21:12:08.925" endtime="20230806 21:12:09.045"/>
</suite>
<status status="FAIL" starttime="20230806 21:12:08.427" endtime="20230806 21:12:09.048"/>
</suite>
<statistics>
<total>
<stat pass="3" fail="1" skip="0">All Tests</stat>
</total>
<tag>
<stat pass="3" fail="1" skip="0">demo</stat>
<stat pass="2" fail="0" skip="0">getuser</stat>
<stat pass="0" fail="1" skip="0">regression</stat>
<stat pass="1" fail="0" skip="0">updateUser</stat>
</tag>
<suite>
<stat pass="3" fail="1" skip="0" id="s1" name="Functional Tests">Functional Tests</stat>
<stat pass="2" fail="0" skip="0" id="s1-s1" name="getUser">Functional Tests.getUser</stat>
<stat pass="0" fail="1" skip="0" id="s1-s2" name="Login">Functional Tests.Login</stat>
<stat pass="1" fail="0" skip="0" id="s1-s3" name="updateUser">Functional Tests.updateUser</stat>
</suite>
</statistics>
<errors>
<msg timestamp="20230806 21:12:08.483" level="ERROR">Error in file 'C:\Users\piyat\source\repos\Demo_API_AutomationTest_RobotFramwork\imports\library.robot' on line 5: Importing library 'RequestsLibrary' failed: ImportError: cannot import name 'Mapping' from 'collections' (C:\Program Files\WindowsApps\PythonSoftwareFoundation.Python.3.10_3.10.3056.0_x64__qbz5n2kfra8p0\lib\collections\__init__.py)
Traceback (most recent call last):
  File "C:\Users\piyat\AppData\Local\Packages\PythonSoftwareFoundation.Python.3.10_qbz5n2kfra8p0\LocalCache\local-packages\Python310\site-packages\RequestsLibrary\__init__.py", line 1, in &lt;module&gt;
    from .DeprecatedKeywords import DeprecatedKeywords
  File "C:\Users\piyat\AppData\Local\Packages\PythonSoftwareFoundation.Python.3.10_qbz5n2kfra8p0\LocalCache\local-packages\Python310\site-packages\RequestsLibrary\DeprecatedKeywords.py", line 6, in &lt;module&gt;
    from RequestsLibrary import utils
  File "C:\Users\piyat\AppData\Local\Packages\PythonSoftwareFoundation.Python.3.10_qbz5n2kfra8p0\LocalCache\local-packages\Python310\site-packages\RequestsLibrary\utils.py", line 5, in &lt;module&gt;
    from requests.status_codes import codes
  File "C:\Users\piyat\AppData\Local\Packages\PythonSoftwareFoundation.Python.3.10_qbz5n2kfra8p0\LocalCache\local-packages\Python310\site-packages\requests\__init__.py", line 43, in &lt;module&gt;
    import urllib3
  File "C:\Users\piyat\AppData\Local\Packages\PythonSoftwareFoundation.Python.3.10_qbz5n2kfra8p0\LocalCache\local-packages\Python310\site-packages\urllib3\__init__.py", line 8, in &lt;module&gt;
    from .connectionpool import (
  File "C:\Users\piyat\AppData\Local\Packages\PythonSoftwareFoundation.Python.3.10_qbz5n2kfra8p0\LocalCache\local-packages\Python310\site-packages\urllib3\connectionpool.py", line 29, in &lt;module&gt;
    from .connection import (
  File "C:\Users\piyat\AppData\Local\Packages\PythonSoftwareFoundation.Python.3.10_qbz5n2kfra8p0\LocalCache\local-packages\Python310\site-packages\urllib3\connection.py", line 39, in &lt;module&gt;
    from .util.ssl_ import (
  File "C:\Users\piyat\AppData\Local\Packages\PythonSoftwareFoundation.Python.3.10_qbz5n2kfra8p0\LocalCache\local-packages\Python310\site-packages\urllib3\util\__init__.py", line 3, in &lt;module&gt;
    from .connection import is_connection_dropped
  File "C:\Users\piyat\AppData\Local\Packages\PythonSoftwareFoundation.Python.3.10_qbz5n2kfra8p0\LocalCache\local-packages\Python310\site-packages\urllib3\util\connection.py", line 3, in &lt;module&gt;
    from .wait import wait_for_read
  File "C:\Users\piyat\AppData\Local\Packages\PythonSoftwareFoundation.Python.3.10_qbz5n2kfra8p0\LocalCache\local-packages\Python310\site-packages\urllib3\util\wait.py", line 1, in &lt;module&gt;
    from .selectors import (
  File "C:\Users\piyat\AppData\Local\Packages\PythonSoftwareFoundation.Python.3.10_qbz5n2kfra8p0\LocalCache\local-packages\Python310\site-packages\urllib3\util\selectors.py", line 14, in &lt;module&gt;
    from collections import namedtuple, Mapping
PYTHONPATH:
  C:\Users\piyat\source\repos\Demo_API_AutomationTest_RobotFramwork
  C:\Program Files\WindowsApps\PythonSoftwareFoundation.Python.3.10_3.10.3056.0_x64__qbz5n2kfra8p0\python310.zip
  C:\Program Files\WindowsApps\PythonSoftwareFoundation.Python.3.10_3.10.3056.0_x64__qbz5n2kfra8p0\DLLs
  C:\Program Files\WindowsApps\PythonSoftwareFoundation.Python.3.10_3.10.3056.0_x64__qbz5n2kfra8p0\lib
  C:\Users\piyat\AppData\Local\Microsoft\WindowsApps\PythonSoftwareFoundation.Python.3.10_qbz5n2kfra8p0
  C:\Users\piyat\AppData\Local\Packages\PythonSoftwareFoundation.Python.3.10_qbz5n2kfra8p0\LocalCache\local-packages\Python310\site-packages
  C:\Program Files\WindowsApps\PythonSoftwareFoundation.Python.3.10_3.10.3056.0_x64__qbz5n2kfra8p0
  C:\Program Files\WindowsApps\PythonSoftwareFoundation.Python.3.10_3.10.3056.0_x64__qbz5n2kfra8p0\lib\site-packages</msg>
<msg timestamp="20230806 21:12:08.538" level="ERROR">Error in file 'C:\Users\piyat\source\repos\Demo_API_AutomationTest_RobotFramwork\imports\library.robot' on line 7: Importing library 'REST' failed: ImportError: cannot import name 'Mapping' from 'collections' (C:\Program Files\WindowsApps\PythonSoftwareFoundation.Python.3.10_3.10.3056.0_x64__qbz5n2kfra8p0\lib\collections\__init__.py)
Traceback (most recent call last):
  File "C:\Users\piyat\AppData\Local\Packages\PythonSoftwareFoundation.Python.3.10_qbz5n2kfra8p0\LocalCache\local-packages\Python310\site-packages\REST\__init__.py", line 28, in &lt;module&gt;
    from requests.packages.urllib3 import disable_warnings
  File "C:\Users\piyat\AppData\Local\Packages\PythonSoftwareFoundation.Python.3.10_qbz5n2kfra8p0\LocalCache\local-packages\Python310\site-packages\requests\__init__.py", line 43, in &lt;module&gt;
    import urllib3
  File "C:\Users\piyat\AppData\Local\Packages\PythonSoftwareFoundation.Python.3.10_qbz5n2kfra8p0\LocalCache\local-packages\Python310\site-packages\urllib3\__init__.py", line 8, in &lt;module&gt;
    from .connectionpool import (
  File "C:\Users\piyat\AppData\Local\Packages\PythonSoftwareFoundation.Python.3.10_qbz5n2kfra8p0\LocalCache\local-packages\Python310\site-packages\urllib3\connectionpool.py", line 29, in &lt;module&gt;
    from .connection import (
  File "C:\Users\piyat\AppData\Local\Packages\PythonSoftwareFoundation.Python.3.10_qbz5n2kfra8p0\LocalCache\local-packages\Python310\site-packages\urllib3\connection.py", line 39, in &lt;module&gt;
    from .util.ssl_ import (
  File "C:\Users\piyat\AppData\Local\Packages\PythonSoftwareFoundation.Python.3.10_qbz5n2kfra8p0\LocalCache\local-packages\Python310\site-packages\urllib3\util\__init__.py", line 3, in &lt;module&gt;
    from .connection import is_connection_dropped
  File "C:\Users\piyat\AppData\Local\Packages\PythonSoftwareFoundation.Python.3.10_qbz5n2kfra8p0\LocalCache\local-packages\Python310\site-packages\urllib3\util\connection.py", line 3, in &lt;module&gt;
    from .wait import wait_for_read
  File "C:\Users\piyat\AppData\Local\Packages\PythonSoftwareFoundation.Python.3.10_qbz5n2kfra8p0\LocalCache\local-packages\Python310\site-packages\urllib3\util\wait.py", line 1, in &lt;module&gt;
    from .selectors import (
  File "C:\Users\piyat\AppData\Local\Packages\PythonSoftwareFoundation.Python.3.10_qbz5n2kfra8p0\LocalCache\local-packages\Python310\site-packages\urllib3\util\selectors.py", line 14, in &lt;module&gt;
    from collections import namedtuple, Mapping
PYTHONPATH:
  C:\Users\piyat\source\repos\Demo_API_AutomationTest_RobotFramwork
  C:\Program Files\WindowsApps\PythonSoftwareFoundation.Python.3.10_3.10.3056.0_x64__qbz5n2kfra8p0\python310.zip
  C:\Program Files\WindowsApps\PythonSoftwareFoundation.Python.3.10_3.10.3056.0_x64__qbz5n2kfra8p0\DLLs
  C:\Program Files\WindowsApps\PythonSoftwareFoundation.Python.3.10_3.10.3056.0_x64__qbz5n2kfra8p0\lib
  C:\Users\piyat\AppData\Local\Microsoft\WindowsApps\PythonSoftwareFoundation.Python.3.10_qbz5n2kfra8p0
  C:\Users\piyat\AppData\Local\Packages\PythonSoftwareFoundation.Python.3.10_qbz5n2kfra8p0\LocalCache\local-packages\Python310\site-packages
  C:\Program Files\WindowsApps\PythonSoftwareFoundation.Python.3.10_3.10.3056.0_x64__qbz5n2kfra8p0
  C:\Program Files\WindowsApps\PythonSoftwareFoundation.Python.3.10_3.10.3056.0_x64__qbz5n2kfra8p0\lib\site-packages</msg>
<msg timestamp="20230806 21:12:08.575" level="ERROR">Error in file 'C:\Users\piyat\source\repos\Demo_API_AutomationTest_RobotFramwork\imports\library.robot' on line 8: Importing library 'SeleniumLibrary' failed: ImportError: cannot import name 'Mapping' from 'collections' (C:\Program Files\WindowsApps\PythonSoftwareFoundation.Python.3.10_3.10.3056.0_x64__qbz5n2kfra8p0\lib\collections\__init__.py)
Traceback (most recent call last):
  File "C:\Users\piyat\AppData\Local\Packages\PythonSoftwareFoundation.Python.3.10_qbz5n2kfra8p0\LocalCache\local-packages\Python310\site-packages\SeleniumLibrary\__init__.py", line 28, in &lt;module&gt;
    from selenium.webdriver.remote.webdriver import WebDriver
  File "C:\Users\piyat\AppData\Local\Packages\PythonSoftwareFoundation.Python.3.10_qbz5n2kfra8p0\LocalCache\local-packages\Python310\site-packages\selenium\webdriver\__init__.py", line 18, in &lt;module&gt;
    from .firefox.webdriver import WebDriver as Firefox  # noqa
  File "C:\Users\piyat\AppData\Local\Packages\PythonSoftwareFoundation.Python.3.10_qbz5n2kfra8p0\LocalCache\local-packages\Python310\site-packages\selenium\webdriver\firefox\webdriver.py", line 29, in &lt;module&gt;
    from selenium.webdriver.remote.webdriver import WebDriver as RemoteWebDriver
  File "C:\Users\piyat\AppData\Local\Packages\PythonSoftwareFoundation.Python.3.10_qbz5n2kfra8p0\LocalCache\local-packages\Python310\site-packages\selenium\webdriver\remote\webdriver.py", line 27, in &lt;module&gt;
    from .remote_connection import RemoteConnection
  File "C:\Users\piyat\AppData\Local\Packages\PythonSoftwareFoundation.Python.3.10_qbz5n2kfra8p0\LocalCache\local-packages\Python310\site-packages\selenium\webdriver\remote\remote_connection.py", line 24, in &lt;module&gt;
    import urllib3
  File "C:\Users\piyat\AppData\Local\Packages\PythonSoftwareFoundation.Python.3.10_qbz5n2kfra8p0\LocalCache\local-packages\Python310\site-packages\urllib3\__init__.py", line 8, in &lt;module&gt;
    from .connectionpool import (
  File "C:\Users\piyat\AppData\Local\Packages\PythonSoftwareFoundation.Python.3.10_qbz5n2kfra8p0\LocalCache\local-packages\Python310\site-packages\urllib3\connectionpool.py", line 29, in &lt;module&gt;
    from .connection import (
  File "C:\Users\piyat\AppData\Local\Packages\PythonSoftwareFoundation.Python.3.10_qbz5n2kfra8p0\LocalCache\local-packages\Python310\site-packages\urllib3\connection.py", line 39, in &lt;module&gt;
    from .util.ssl_ import (
  File "C:\Users\piyat\AppData\Local\Packages\PythonSoftwareFoundation.Python.3.10_qbz5n2kfra8p0\LocalCache\local-packages\Python310\site-packages\urllib3\util\__init__.py", line 3, in &lt;module&gt;
    from .connection import is_connection_dropped
  File "C:\Users\piyat\AppData\Local\Packages\PythonSoftwareFoundation.Python.3.10_qbz5n2kfra8p0\LocalCache\local-packages\Python310\site-packages\urllib3\util\connection.py", line 3, in &lt;module&gt;
    from .wait import wait_for_read
  File "C:\Users\piyat\AppData\Local\Packages\PythonSoftwareFoundation.Python.3.10_qbz5n2kfra8p0\LocalCache\local-packages\Python310\site-packages\urllib3\util\wait.py", line 1, in &lt;module&gt;
    from .selectors import (
  File "C:\Users\piyat\AppData\Local\Packages\PythonSoftwareFoundation.Python.3.10_qbz5n2kfra8p0\LocalCache\local-packages\Python310\site-packages\urllib3\util\selectors.py", line 14, in &lt;module&gt;
    from collections import namedtuple, Mapping
PYTHONPATH:
  C:\Users\piyat\source\repos\Demo_API_AutomationTest_RobotFramwork
  C:\Program Files\WindowsApps\PythonSoftwareFoundation.Python.3.10_3.10.3056.0_x64__qbz5n2kfra8p0\python310.zip
  C:\Program Files\WindowsApps\PythonSoftwareFoundation.Python.3.10_3.10.3056.0_x64__qbz5n2kfra8p0\DLLs
  C:\Program Files\WindowsApps\PythonSoftwareFoundation.Python.3.10_3.10.3056.0_x64__qbz5n2kfra8p0\lib
  C:\Users\piyat\AppData\Local\Microsoft\WindowsApps\PythonSoftwareFoundation.Python.3.10_qbz5n2kfra8p0
  C:\Users\piyat\AppData\Local\Packages\PythonSoftwareFoundation.Python.3.10_qbz5n2kfra8p0\LocalCache\local-packages\Python310\site-packages
  C:\Program Files\WindowsApps\PythonSoftwareFoundation.Python.3.10_3.10.3056.0_x64__qbz5n2kfra8p0
  C:\Program Files\WindowsApps\PythonSoftwareFoundation.Python.3.10_3.10.3056.0_x64__qbz5n2kfra8p0\lib\site-packages</msg>
<msg timestamp="20230806 21:12:08.601" level="ERROR">Error in file 'C:\Users\piyat\source\repos\Demo_API_AutomationTest_RobotFramwork\imports\library.robot' on line 9: Importing library 'AppiumLibrary' failed: ImportError: cannot import name 'Mapping' from 'collections' (C:\Program Files\WindowsApps\PythonSoftwareFoundation.Python.3.10_3.10.3056.0_x64__qbz5n2kfra8p0\lib\collections\__init__.py)
Traceback (most recent call last):
  File "C:\Users\piyat\AppData\Local\Packages\PythonSoftwareFoundation.Python.3.10_qbz5n2kfra8p0\LocalCache\local-packages\Python310\site-packages\AppiumLibrary\__init__.py", line 4, in &lt;module&gt;
    from AppiumLibrary.keywords import *
  File "C:\Users\piyat\AppData\Local\Packages\PythonSoftwareFoundation.Python.3.10_qbz5n2kfra8p0\LocalCache\local-packages\Python310\site-packages\AppiumLibrary\keywords\__init__.py", line 7, in &lt;module&gt;
    from ._applicationmanagement import _ApplicationManagementKeywords
  File "C:\Users\piyat\AppData\Local\Packages\PythonSoftwareFoundation.Python.3.10_qbz5n2kfra8p0\LocalCache\local-packages\Python310\site-packages\AppiumLibrary\keywords\_applicationmanagement.py", line 6, in &lt;module&gt;
    from appium import webdriver
  File "C:\Users\piyat\AppData\Local\Packages\PythonSoftwareFoundation.Python.3.10_qbz5n2kfra8p0\LocalCache\local-packages\Python310\site-packages\appium\webdriver\__init__.py", line 19, in &lt;module&gt;
    from .webdriver import WebDriver as Remote
  File "C:\Users\piyat\AppData\Local\Packages\PythonSoftwareFoundation.Python.3.10_qbz5n2kfra8p0\LocalCache\local-packages\Python310\site-packages\appium\webdriver\webdriver.py", line 23, in &lt;module&gt;
    from selenium.webdriver.remote.remote_connection import RemoteConnection
  File "C:\Users\piyat\AppData\Local\Packages\PythonSoftwareFoundation.Python.3.10_qbz5n2kfra8p0\LocalCache\local-packages\Python310\site-packages\selenium\webdriver\remote\remote_connection.py", line 24, in &lt;module&gt;
    import urllib3
  File "C:\Users\piyat\AppData\Local\Packages\PythonSoftwareFoundation.Python.3.10_qbz5n2kfra8p0\LocalCache\local-packages\Python310\site-packages\urllib3\__init__.py", line 8, in &lt;module&gt;
    from .connectionpool import (
  File "C:\Users\piyat\AppData\Local\Packages\PythonSoftwareFoundation.Python.3.10_qbz5n2kfra8p0\LocalCache\local-packages\Python310\site-packages\urllib3\connectionpool.py", line 29, in &lt;module&gt;
    from .connection import (
  File "C:\Users\piyat\AppData\Local\Packages\PythonSoftwareFoundation.Python.3.10_qbz5n2kfra8p0\LocalCache\local-packages\Python310\site-packages\urllib3\connection.py", line 39, in &lt;module&gt;
    from .util.ssl_ import (
  File "C:\Users\piyat\AppData\Local\Packages\PythonSoftwareFoundation.Python.3.10_qbz5n2kfra8p0\LocalCache\local-packages\Python310\site-packages\urllib3\util\__init__.py", line 3, in &lt;module&gt;
    from .connection import is_connection_dropped
  File "C:\Users\piyat\AppData\Local\Packages\PythonSoftwareFoundation.Python.3.10_qbz5n2kfra8p0\LocalCache\local-packages\Python310\site-packages\urllib3\util\connection.py", line 3, in &lt;module&gt;
    from .wait import wait_for_read
  File "C:\Users\piyat\AppData\Local\Packages\PythonSoftwareFoundation.Python.3.10_qbz5n2kfra8p0\LocalCache\local-packages\Python310\site-packages\urllib3\util\wait.py", line 1, in &lt;module&gt;
    from .selectors import (
  File "C:\Users\piyat\AppData\Local\Packages\PythonSoftwareFoundation.Python.3.10_qbz5n2kfra8p0\LocalCache\local-packages\Python310\site-packages\urllib3\util\selectors.py", line 14, in &lt;module&gt;
    from collections import namedtuple, Mapping
PYTHONPATH:
  C:\Users\piyat\source\repos\Demo_API_AutomationTest_RobotFramwork
  C:\Program Files\WindowsApps\PythonSoftwareFoundation.Python.3.10_3.10.3056.0_x64__qbz5n2kfra8p0\python310.zip
  C:\Program Files\WindowsApps\PythonSoftwareFoundation.Python.3.10_3.10.3056.0_x64__qbz5n2kfra8p0\DLLs
  C:\Program Files\WindowsApps\PythonSoftwareFoundation.Python.3.10_3.10.3056.0_x64__qbz5n2kfra8p0\lib
  C:\Users\piyat\AppData\Local\Microsoft\WindowsApps\PythonSoftwareFoundation.Python.3.10_qbz5n2kfra8p0
  C:\Users\piyat\AppData\Local\Packages\PythonSoftwareFoundation.Python.3.10_qbz5n2kfra8p0\LocalCache\local-packages\Python310\site-packages
  C:\Program Files\WindowsApps\PythonSoftwareFoundation.Python.3.10_3.10.3056.0_x64__qbz5n2kfra8p0
  C:\Program Files\WindowsApps\PythonSoftwareFoundation.Python.3.10_3.10.3056.0_x64__qbz5n2kfra8p0\lib\site-packages</msg>
<msg timestamp="20230806 21:12:08.756" level="ERROR">Error in file 'C:\Users\piyat\source\repos\Demo_API_AutomationTest_RobotFramwork\imports\library.robot' on line 20: Importing library 'TestRail' failed: ModuleNotFoundError: No module named 'TestRail'
Traceback (most recent call last):
  None
PYTHONPATH:
  C:\Users\piyat\source\repos\Demo_API_AutomationTest_RobotFramwork
  C:\Program Files\WindowsApps\PythonSoftwareFoundation.Python.3.10_3.10.3056.0_x64__qbz5n2kfra8p0\python310.zip
  C:\Program Files\WindowsApps\PythonSoftwareFoundation.Python.3.10_3.10.3056.0_x64__qbz5n2kfra8p0\DLLs
  C:\Program Files\WindowsApps\PythonSoftwareFoundation.Python.3.10_3.10.3056.0_x64__qbz5n2kfra8p0\lib
  C:\Users\piyat\AppData\Local\Microsoft\WindowsApps\PythonSoftwareFoundation.Python.3.10_qbz5n2kfra8p0
  C:\Users\piyat\AppData\Local\Packages\PythonSoftwareFoundation.Python.3.10_qbz5n2kfra8p0\LocalCache\local-packages\Python310\site-packages
  C:\Program Files\WindowsApps\PythonSoftwareFoundation.Python.3.10_3.10.3056.0_x64__qbz5n2kfra8p0
  C:\Program Files\WindowsApps\PythonSoftwareFoundation.Python.3.10_3.10.3056.0_x64__qbz5n2kfra8p0\lib\site-packages</msg>
<msg timestamp="20230806 21:12:08.783" level="ERROR">Error in file 'C:\Users\piyat\source\repos\Demo_API_AutomationTest_RobotFramwork\keywords\endpoint\account_management.robot' on line 2: Importing library 'REST' failed: ImportError: cannot import name 'Mapping' from 'collections' (C:\Program Files\WindowsApps\PythonSoftwareFoundation.Python.3.10_3.10.3056.0_x64__qbz5n2kfra8p0\lib\collections\__init__.py)
Traceback (most recent call last):
  File "C:\Users\piyat\AppData\Local\Packages\PythonSoftwareFoundation.Python.3.10_qbz5n2kfra8p0\LocalCache\local-packages\Python310\site-packages\REST\__init__.py", line 28, in &lt;module&gt;
    from requests.packages.urllib3 import disable_warnings
  File "C:\Users\piyat\AppData\Local\Packages\PythonSoftwareFoundation.Python.3.10_qbz5n2kfra8p0\LocalCache\local-packages\Python310\site-packages\requests\__init__.py", line 43, in &lt;module&gt;
    import urllib3
  File "C:\Users\piyat\AppData\Local\Packages\PythonSoftwareFoundation.Python.3.10_qbz5n2kfra8p0\LocalCache\local-packages\Python310\site-packages\urllib3\__init__.py", line 8, in &lt;module&gt;
    from .connectionpool import (
  File "C:\Users\piyat\AppData\Local\Packages\PythonSoftwareFoundation.Python.3.10_qbz5n2kfra8p0\LocalCache\local-packages\Python310\site-packages\urllib3\connectionpool.py", line 29, in &lt;module&gt;
    from .connection import (
  File "C:\Users\piyat\AppData\Local\Packages\PythonSoftwareFoundation.Python.3.10_qbz5n2kfra8p0\LocalCache\local-packages\Python310\site-packages\urllib3\connection.py", line 39, in &lt;module&gt;
    from .util.ssl_ import (
  File "C:\Users\piyat\AppData\Local\Packages\PythonSoftwareFoundation.Python.3.10_qbz5n2kfra8p0\LocalCache\local-packages\Python310\site-packages\urllib3\util\__init__.py", line 3, in &lt;module&gt;
    from .connection import is_connection_dropped
  File "C:\Users\piyat\AppData\Local\Packages\PythonSoftwareFoundation.Python.3.10_qbz5n2kfra8p0\LocalCache\local-packages\Python310\site-packages\urllib3\util\connection.py", line 3, in &lt;module&gt;
    from .wait import wait_for_read
  File "C:\Users\piyat\AppData\Local\Packages\PythonSoftwareFoundation.Python.3.10_qbz5n2kfra8p0\LocalCache\local-packages\Python310\site-packages\urllib3\util\wait.py", line 1, in &lt;module&gt;
    from .selectors import (
  File "C:\Users\piyat\AppData\Local\Packages\PythonSoftwareFoundation.Python.3.10_qbz5n2kfra8p0\LocalCache\local-packages\Python310\site-packages\urllib3\util\selectors.py", line 14, in &lt;module&gt;
    from collections import namedtuple, Mapping
PYTHONPATH:
  C:\Users\piyat\source\repos\Demo_API_AutomationTest_RobotFramwork
  C:\Program Files\WindowsApps\PythonSoftwareFoundation.Python.3.10_3.10.3056.0_x64__qbz5n2kfra8p0\python310.zip
  C:\Program Files\WindowsApps\PythonSoftwareFoundation.Python.3.10_3.10.3056.0_x64__qbz5n2kfra8p0\DLLs
  C:\Program Files\WindowsApps\PythonSoftwareFoundation.Python.3.10_3.10.3056.0_x64__qbz5n2kfra8p0\lib
  C:\Users\piyat\AppData\Local\Microsoft\WindowsApps\PythonSoftwareFoundation.Python.3.10_qbz5n2kfra8p0
  C:\Users\piyat\AppData\Local\Packages\PythonSoftwareFoundation.Python.3.10_qbz5n2kfra8p0\LocalCache\local-packages\Python310\site-packages
  C:\Program Files\WindowsApps\PythonSoftwareFoundation.Python.3.10_3.10.3056.0_x64__qbz5n2kfra8p0
  C:\Program Files\WindowsApps\PythonSoftwareFoundation.Python.3.10_3.10.3056.0_x64__qbz5n2kfra8p0\lib\site-packages</msg>
<msg timestamp="20230806 21:12:08.826" level="ERROR">Error in file 'C:\Users\piyat\source\repos\Demo_API_AutomationTest_RobotFramwork\imports\library.robot' on line 5: Importing library 'RequestsLibrary' failed: ImportError: cannot import name 'Mapping' from 'collections' (C:\Program Files\WindowsApps\PythonSoftwareFoundation.Python.3.10_3.10.3056.0_x64__qbz5n2kfra8p0\lib\collections\__init__.py)
Traceback (most recent call last):
  File "C:\Users\piyat\AppData\Local\Packages\PythonSoftwareFoundation.Python.3.10_qbz5n2kfra8p0\LocalCache\local-packages\Python310\site-packages\RequestsLibrary\__init__.py", line 1, in &lt;module&gt;
    from .DeprecatedKeywords import DeprecatedKeywords
  File "C:\Users\piyat\AppData\Local\Packages\PythonSoftwareFoundation.Python.3.10_qbz5n2kfra8p0\LocalCache\local-packages\Python310\site-packages\RequestsLibrary\DeprecatedKeywords.py", line 6, in &lt;module&gt;
    from RequestsLibrary import utils
  File "C:\Users\piyat\AppData\Local\Packages\PythonSoftwareFoundation.Python.3.10_qbz5n2kfra8p0\LocalCache\local-packages\Python310\site-packages\RequestsLibrary\utils.py", line 5, in &lt;module&gt;
    from requests.status_codes import codes
  File "C:\Users\piyat\AppData\Local\Packages\PythonSoftwareFoundation.Python.3.10_qbz5n2kfra8p0\LocalCache\local-packages\Python310\site-packages\requests\__init__.py", line 43, in &lt;module&gt;
    import urllib3
  File "C:\Users\piyat\AppData\Local\Packages\PythonSoftwareFoundation.Python.3.10_qbz5n2kfra8p0\LocalCache\local-packages\Python310\site-packages\urllib3\__init__.py", line 8, in &lt;module&gt;
    from .connectionpool import (
  File "C:\Users\piyat\AppData\Local\Packages\PythonSoftwareFoundation.Python.3.10_qbz5n2kfra8p0\LocalCache\local-packages\Python310\site-packages\urllib3\connectionpool.py", line 29, in &lt;module&gt;
    from .connection import (
  File "C:\Users\piyat\AppData\Local\Packages\PythonSoftwareFoundation.Python.3.10_qbz5n2kfra8p0\LocalCache\local-packages\Python310\site-packages\urllib3\connection.py", line 39, in &lt;module&gt;
    from .util.ssl_ import (
  File "C:\Users\piyat\AppData\Local\Packages\PythonSoftwareFoundation.Python.3.10_qbz5n2kfra8p0\LocalCache\local-packages\Python310\site-packages\urllib3\util\__init__.py", line 3, in &lt;module&gt;
    from .connection import is_connection_dropped
  File "C:\Users\piyat\AppData\Local\Packages\PythonSoftwareFoundation.Python.3.10_qbz5n2kfra8p0\LocalCache\local-packages\Python310\site-packages\urllib3\util\connection.py", line 3, in &lt;module&gt;
    from .wait import wait_for_read
  File "C:\Users\piyat\AppData\Local\Packages\PythonSoftwareFoundation.Python.3.10_qbz5n2kfra8p0\LocalCache\local-packages\Python310\site-packages\urllib3\util\wait.py", line 1, in &lt;module&gt;
    from .selectors import (
  File "C:\Users\piyat\AppData\Local\Packages\PythonSoftwareFoundation.Python.3.10_qbz5n2kfra8p0\LocalCache\local-packages\Python310\site-packages\urllib3\util\selectors.py", line 14, in &lt;module&gt;
    from collections import namedtuple, Mapping
PYTHONPATH:
  C:\Users\piyat\source\repos\Demo_API_AutomationTest_RobotFramwork
  C:\Program Files\WindowsApps\PythonSoftwareFoundation.Python.3.10_3.10.3056.0_x64__qbz5n2kfra8p0\python310.zip
  C:\Program Files\WindowsApps\PythonSoftwareFoundation.Python.3.10_3.10.3056.0_x64__qbz5n2kfra8p0\DLLs
  C:\Program Files\WindowsApps\PythonSoftwareFoundation.Python.3.10_3.10.3056.0_x64__qbz5n2kfra8p0\lib
  C:\Users\piyat\AppData\Local\Microsoft\WindowsApps\PythonSoftwareFoundation.Python.3.10_qbz5n2kfra8p0
  C:\Users\piyat\AppData\Local\Packages\PythonSoftwareFoundation.Python.3.10_qbz5n2kfra8p0\LocalCache\local-packages\Python310\site-packages
  C:\Program Files\WindowsApps\PythonSoftwareFoundation.Python.3.10_3.10.3056.0_x64__qbz5n2kfra8p0
  C:\Program Files\WindowsApps\PythonSoftwareFoundation.Python.3.10_3.10.3056.0_x64__qbz5n2kfra8p0\lib\site-packages</msg>
<msg timestamp="20230806 21:12:08.843" level="ERROR">Error in file 'C:\Users\piyat\source\repos\Demo_API_AutomationTest_RobotFramwork\imports\library.robot' on line 7: Importing library 'REST' failed: ImportError: cannot import name 'Mapping' from 'collections' (C:\Program Files\WindowsApps\PythonSoftwareFoundation.Python.3.10_3.10.3056.0_x64__qbz5n2kfra8p0\lib\collections\__init__.py)
Traceback (most recent call last):
  File "C:\Users\piyat\AppData\Local\Packages\PythonSoftwareFoundation.Python.3.10_qbz5n2kfra8p0\LocalCache\local-packages\Python310\site-packages\REST\__init__.py", line 28, in &lt;module&gt;
    from requests.packages.urllib3 import disable_warnings
  File "C:\Users\piyat\AppData\Local\Packages\PythonSoftwareFoundation.Python.3.10_qbz5n2kfra8p0\LocalCache\local-packages\Python310\site-packages\requests\__init__.py", line 43, in &lt;module&gt;
    import urllib3
  File "C:\Users\piyat\AppData\Local\Packages\PythonSoftwareFoundation.Python.3.10_qbz5n2kfra8p0\LocalCache\local-packages\Python310\site-packages\urllib3\__init__.py", line 8, in &lt;module&gt;
    from .connectionpool import (
  File "C:\Users\piyat\AppData\Local\Packages\PythonSoftwareFoundation.Python.3.10_qbz5n2kfra8p0\LocalCache\local-packages\Python310\site-packages\urllib3\connectionpool.py", line 29, in &lt;module&gt;
    from .connection import (
  File "C:\Users\piyat\AppData\Local\Packages\PythonSoftwareFoundation.Python.3.10_qbz5n2kfra8p0\LocalCache\local-packages\Python310\site-packages\urllib3\connection.py", line 39, in &lt;module&gt;
    from .util.ssl_ import (
  File "C:\Users\piyat\AppData\Local\Packages\PythonSoftwareFoundation.Python.3.10_qbz5n2kfra8p0\LocalCache\local-packages\Python310\site-packages\urllib3\util\__init__.py", line 3, in &lt;module&gt;
    from .connection import is_connection_dropped
  File "C:\Users\piyat\AppData\Local\Packages\PythonSoftwareFoundation.Python.3.10_qbz5n2kfra8p0\LocalCache\local-packages\Python310\site-packages\urllib3\util\connection.py", line 3, in &lt;module&gt;
    from .wait import wait_for_read
  File "C:\Users\piyat\AppData\Local\Packages\PythonSoftwareFoundation.Python.3.10_qbz5n2kfra8p0\LocalCache\local-packages\Python310\site-packages\urllib3\util\wait.py", line 1, in &lt;module&gt;
    from .selectors import (
  File "C:\Users\piyat\AppData\Local\Packages\PythonSoftwareFoundation.Python.3.10_qbz5n2kfra8p0\LocalCache\local-packages\Python310\site-packages\urllib3\util\selectors.py", line 14, in &lt;module&gt;
    from collections import namedtuple, Mapping
PYTHONPATH:
  C:\Users\piyat\source\repos\Demo_API_AutomationTest_RobotFramwork
  C:\Program Files\WindowsApps\PythonSoftwareFoundation.Python.3.10_3.10.3056.0_x64__qbz5n2kfra8p0\python310.zip
  C:\Program Files\WindowsApps\PythonSoftwareFoundation.Python.3.10_3.10.3056.0_x64__qbz5n2kfra8p0\DLLs
  C:\Program Files\WindowsApps\PythonSoftwareFoundation.Python.3.10_3.10.3056.0_x64__qbz5n2kfra8p0\lib
  C:\Users\piyat\AppData\Local\Microsoft\WindowsApps\PythonSoftwareFoundation.Python.3.10_qbz5n2kfra8p0
  C:\Users\piyat\AppData\Local\Packages\PythonSoftwareFoundation.Python.3.10_qbz5n2kfra8p0\LocalCache\local-packages\Python310\site-packages
  C:\Program Files\WindowsApps\PythonSoftwareFoundation.Python.3.10_3.10.3056.0_x64__qbz5n2kfra8p0
  C:\Program Files\WindowsApps\PythonSoftwareFoundation.Python.3.10_3.10.3056.0_x64__qbz5n2kfra8p0\lib\site-packages</msg>
<msg timestamp="20230806 21:12:08.861" level="ERROR">Error in file 'C:\Users\piyat\source\repos\Demo_API_AutomationTest_RobotFramwork\imports\library.robot' on line 8: Importing library 'SeleniumLibrary' failed: ImportError: cannot import name 'Mapping' from 'collections' (C:\Program Files\WindowsApps\PythonSoftwareFoundation.Python.3.10_3.10.3056.0_x64__qbz5n2kfra8p0\lib\collections\__init__.py)
Traceback (most recent call last):
  File "C:\Users\piyat\AppData\Local\Packages\PythonSoftwareFoundation.Python.3.10_qbz5n2kfra8p0\LocalCache\local-packages\Python310\site-packages\SeleniumLibrary\__init__.py", line 28, in &lt;module&gt;
    from selenium.webdriver.remote.webdriver import WebDriver
  File "C:\Users\piyat\AppData\Local\Packages\PythonSoftwareFoundation.Python.3.10_qbz5n2kfra8p0\LocalCache\local-packages\Python310\site-packages\selenium\webdriver\remote\webdriver.py", line 27, in &lt;module&gt;
    from .remote_connection import RemoteConnection
  File "C:\Users\piyat\AppData\Local\Packages\PythonSoftwareFoundation.Python.3.10_qbz5n2kfra8p0\LocalCache\local-packages\Python310\site-packages\selenium\webdriver\remote\remote_connection.py", line 24, in &lt;module&gt;
    import urllib3
  File "C:\Users\piyat\AppData\Local\Packages\PythonSoftwareFoundation.Python.3.10_qbz5n2kfra8p0\LocalCache\local-packages\Python310\site-packages\urllib3\__init__.py", line 8, in &lt;module&gt;
    from .connectionpool import (
  File "C:\Users\piyat\AppData\Local\Packages\PythonSoftwareFoundation.Python.3.10_qbz5n2kfra8p0\LocalCache\local-packages\Python310\site-packages\urllib3\connectionpool.py", line 29, in &lt;module&gt;
    from .connection import (
  File "C:\Users\piyat\AppData\Local\Packages\PythonSoftwareFoundation.Python.3.10_qbz5n2kfra8p0\LocalCache\local-packages\Python310\site-packages\urllib3\connection.py", line 39, in &lt;module&gt;
    from .util.ssl_ import (
  File "C:\Users\piyat\AppData\Local\Packages\PythonSoftwareFoundation.Python.3.10_qbz5n2kfra8p0\LocalCache\local-packages\Python310\site-packages\urllib3\util\__init__.py", line 3, in &lt;module&gt;
    from .connection import is_connection_dropped
  File "C:\Users\piyat\AppData\Local\Packages\PythonSoftwareFoundation.Python.3.10_qbz5n2kfra8p0\LocalCache\local-packages\Python310\site-packages\urllib3\util\connection.py", line 3, in &lt;module&gt;
    from .wait import wait_for_read
  File "C:\Users\piyat\AppData\Local\Packages\PythonSoftwareFoundation.Python.3.10_qbz5n2kfra8p0\LocalCache\local-packages\Python310\site-packages\urllib3\util\wait.py", line 1, in &lt;module&gt;
    from .selectors import (
  File "C:\Users\piyat\AppData\Local\Packages\PythonSoftwareFoundation.Python.3.10_qbz5n2kfra8p0\LocalCache\local-packages\Python310\site-packages\urllib3\util\selectors.py", line 14, in &lt;module&gt;
    from collections import namedtuple, Mapping
PYTHONPATH:
  C:\Users\piyat\source\repos\Demo_API_AutomationTest_RobotFramwork
  C:\Program Files\WindowsApps\PythonSoftwareFoundation.Python.3.10_3.10.3056.0_x64__qbz5n2kfra8p0\python310.zip
  C:\Program Files\WindowsApps\PythonSoftwareFoundation.Python.3.10_3.10.3056.0_x64__qbz5n2kfra8p0\DLLs
  C:\Program Files\WindowsApps\PythonSoftwareFoundation.Python.3.10_3.10.3056.0_x64__qbz5n2kfra8p0\lib
  C:\Users\piyat\AppData\Local\Microsoft\WindowsApps\PythonSoftwareFoundation.Python.3.10_qbz5n2kfra8p0
  C:\Users\piyat\AppData\Local\Packages\PythonSoftwareFoundation.Python.3.10_qbz5n2kfra8p0\LocalCache\local-packages\Python310\site-packages
  C:\Program Files\WindowsApps\PythonSoftwareFoundation.Python.3.10_3.10.3056.0_x64__qbz5n2kfra8p0
  C:\Program Files\WindowsApps\PythonSoftwareFoundation.Python.3.10_3.10.3056.0_x64__qbz5n2kfra8p0\lib\site-packages</msg>
<msg timestamp="20230806 21:12:08.878" level="ERROR">Error in file 'C:\Users\piyat\source\repos\Demo_API_AutomationTest_RobotFramwork\imports\library.robot' on line 9: Importing library 'AppiumLibrary' failed: ImportError: cannot import name 'Mapping' from 'collections' (C:\Program Files\WindowsApps\PythonSoftwareFoundation.Python.3.10_3.10.3056.0_x64__qbz5n2kfra8p0\lib\collections\__init__.py)
Traceback (most recent call last):
  File "C:\Users\piyat\AppData\Local\Packages\PythonSoftwareFoundation.Python.3.10_qbz5n2kfra8p0\LocalCache\local-packages\Python310\site-packages\AppiumLibrary\__init__.py", line 4, in &lt;module&gt;
    from AppiumLibrary.keywords import *
  File "C:\Users\piyat\AppData\Local\Packages\PythonSoftwareFoundation.Python.3.10_qbz5n2kfra8p0\LocalCache\local-packages\Python310\site-packages\AppiumLibrary\keywords\__init__.py", line 7, in &lt;module&gt;
    from ._applicationmanagement import _ApplicationManagementKeywords
  File "C:\Users\piyat\AppData\Local\Packages\PythonSoftwareFoundation.Python.3.10_qbz5n2kfra8p0\LocalCache\local-packages\Python310\site-packages\AppiumLibrary\keywords\_applicationmanagement.py", line 6, in &lt;module&gt;
    from appium import webdriver
  File "C:\Users\piyat\AppData\Local\Packages\PythonSoftwareFoundation.Python.3.10_qbz5n2kfra8p0\LocalCache\local-packages\Python310\site-packages\appium\webdriver\__init__.py", line 19, in &lt;module&gt;
    from .webdriver import WebDriver as Remote
  File "C:\Users\piyat\AppData\Local\Packages\PythonSoftwareFoundation.Python.3.10_qbz5n2kfra8p0\LocalCache\local-packages\Python310\site-packages\appium\webdriver\webdriver.py", line 23, in &lt;module&gt;
    from selenium.webdriver.remote.remote_connection import RemoteConnection
  File "C:\Users\piyat\AppData\Local\Packages\PythonSoftwareFoundation.Python.3.10_qbz5n2kfra8p0\LocalCache\local-packages\Python310\site-packages\selenium\webdriver\remote\remote_connection.py", line 24, in &lt;module&gt;
    import urllib3
  File "C:\Users\piyat\AppData\Local\Packages\PythonSoftwareFoundation.Python.3.10_qbz5n2kfra8p0\LocalCache\local-packages\Python310\site-packages\urllib3\__init__.py", line 8, in &lt;module&gt;
    from .connectionpool import (
  File "C:\Users\piyat\AppData\Local\Packages\PythonSoftwareFoundation.Python.3.10_qbz5n2kfra8p0\LocalCache\local-packages\Python310\site-packages\urllib3\connectionpool.py", line 29, in &lt;module&gt;
    from .connection import (
  File "C:\Users\piyat\AppData\Local\Packages\PythonSoftwareFoundation.Python.3.10_qbz5n2kfra8p0\LocalCache\local-packages\Python310\site-packages\urllib3\connection.py", line 39, in &lt;module&gt;
    from .util.ssl_ import (
  File "C:\Users\piyat\AppData\Local\Packages\PythonSoftwareFoundation.Python.3.10_qbz5n2kfra8p0\LocalCache\local-packages\Python310\site-packages\urllib3\util\__init__.py", line 3, in &lt;module&gt;
    from .connection import is_connection_dropped
  File "C:\Users\piyat\AppData\Local\Packages\PythonSoftwareFoundation.Python.3.10_qbz5n2kfra8p0\LocalCache\local-packages\Python310\site-packages\urllib3\util\connection.py", line 3, in &lt;module&gt;
    from .wait import wait_for_read
  File "C:\Users\piyat\AppData\Local\Packages\PythonSoftwareFoundation.Python.3.10_qbz5n2kfra8p0\LocalCache\local-packages\Python310\site-packages\urllib3\util\wait.py", line 1, in &lt;module&gt;
    from .selectors import (
  File "C:\Users\piyat\AppData\Local\Packages\PythonSoftwareFoundation.Python.3.10_qbz5n2kfra8p0\LocalCache\local-packages\Python310\site-packages\urllib3\util\selectors.py", line 14, in &lt;module&gt;
    from collections import namedtuple, Mapping
PYTHONPATH:
  C:\Users\piyat\source\repos\Demo_API_AutomationTest_RobotFramwork
  C:\Program Files\WindowsApps\PythonSoftwareFoundation.Python.3.10_3.10.3056.0_x64__qbz5n2kfra8p0\python310.zip
  C:\Program Files\WindowsApps\PythonSoftwareFoundation.Python.3.10_3.10.3056.0_x64__qbz5n2kfra8p0\DLLs
  C:\Program Files\WindowsApps\PythonSoftwareFoundation.Python.3.10_3.10.3056.0_x64__qbz5n2kfra8p0\lib
  C:\Users\piyat\AppData\Local\Microsoft\WindowsApps\PythonSoftwareFoundation.Python.3.10_qbz5n2kfra8p0
  C:\Users\piyat\AppData\Local\Packages\PythonSoftwareFoundation.Python.3.10_qbz5n2kfra8p0\LocalCache\local-packages\Python310\site-packages
  C:\Program Files\WindowsApps\PythonSoftwareFoundation.Python.3.10_3.10.3056.0_x64__qbz5n2kfra8p0
  C:\Program Files\WindowsApps\PythonSoftwareFoundation.Python.3.10_3.10.3056.0_x64__qbz5n2kfra8p0\lib\site-packages</msg>
<msg timestamp="20230806 21:12:08.895" level="ERROR">Error in file 'C:\Users\piyat\source\repos\Demo_API_AutomationTest_RobotFramwork\imports\library.robot' on line 20: Importing library 'TestRail' failed: ModuleNotFoundError: No module named 'TestRail'
Traceback (most recent call last):
  None
PYTHONPATH:
  C:\Users\piyat\source\repos\Demo_API_AutomationTest_RobotFramwork
  C:\Program Files\WindowsApps\PythonSoftwareFoundation.Python.3.10_3.10.3056.0_x64__qbz5n2kfra8p0\python310.zip
  C:\Program Files\WindowsApps\PythonSoftwareFoundation.Python.3.10_3.10.3056.0_x64__qbz5n2kfra8p0\DLLs
  C:\Program Files\WindowsApps\PythonSoftwareFoundation.Python.3.10_3.10.3056.0_x64__qbz5n2kfra8p0\lib
  C:\Users\piyat\AppData\Local\Microsoft\WindowsApps\PythonSoftwareFoundation.Python.3.10_qbz5n2kfra8p0
  C:\Users\piyat\AppData\Local\Packages\PythonSoftwareFoundation.Python.3.10_qbz5n2kfra8p0\LocalCache\local-packages\Python310\site-packages
  C:\Program Files\WindowsApps\PythonSoftwareFoundation.Python.3.10_3.10.3056.0_x64__qbz5n2kfra8p0
  C:\Program Files\WindowsApps\PythonSoftwareFoundation.Python.3.10_3.10.3056.0_x64__qbz5n2kfra8p0\lib\site-packages</msg>
<msg timestamp="20230806 21:12:08.911" level="ERROR">Error in file 'C:\Users\piyat\source\repos\Demo_API_AutomationTest_RobotFramwork\keywords\endpoint\account_management.robot' on line 2: Importing library 'REST' failed: ImportError: cannot import name 'Mapping' from 'collections' (C:\Program Files\WindowsApps\PythonSoftwareFoundation.Python.3.10_3.10.3056.0_x64__qbz5n2kfra8p0\lib\collections\__init__.py)
Traceback (most recent call last):
  File "C:\Users\piyat\AppData\Local\Packages\PythonSoftwareFoundation.Python.3.10_qbz5n2kfra8p0\LocalCache\local-packages\Python310\site-packages\REST\__init__.py", line 28, in &lt;module&gt;
    from requests.packages.urllib3 import disable_warnings
  File "C:\Users\piyat\AppData\Local\Packages\PythonSoftwareFoundation.Python.3.10_qbz5n2kfra8p0\LocalCache\local-packages\Python310\site-packages\requests\__init__.py", line 43, in &lt;module&gt;
    import urllib3
  File "C:\Users\piyat\AppData\Local\Packages\PythonSoftwareFoundation.Python.3.10_qbz5n2kfra8p0\LocalCache\local-packages\Python310\site-packages\urllib3\__init__.py", line 8, in &lt;module&gt;
    from .connectionpool import (
  File "C:\Users\piyat\AppData\Local\Packages\PythonSoftwareFoundation.Python.3.10_qbz5n2kfra8p0\LocalCache\local-packages\Python310\site-packages\urllib3\connectionpool.py", line 29, in &lt;module&gt;
    from .connection import (
  File "C:\Users\piyat\AppData\Local\Packages\PythonSoftwareFoundation.Python.3.10_qbz5n2kfra8p0\LocalCache\local-packages\Python310\site-packages\urllib3\connection.py", line 39, in &lt;module&gt;
    from .util.ssl_ import (
  File "C:\Users\piyat\AppData\Local\Packages\PythonSoftwareFoundation.Python.3.10_qbz5n2kfra8p0\LocalCache\local-packages\Python310\site-packages\urllib3\util\__init__.py", line 3, in &lt;module&gt;
    from .connection import is_connection_dropped
  File "C:\Users\piyat\AppData\Local\Packages\PythonSoftwareFoundation.Python.3.10_qbz5n2kfra8p0\LocalCache\local-packages\Python310\site-packages\urllib3\util\connection.py", line 3, in &lt;module&gt;
    from .wait import wait_for_read
  File "C:\Users\piyat\AppData\Local\Packages\PythonSoftwareFoundation.Python.3.10_qbz5n2kfra8p0\LocalCache\local-packages\Python310\site-packages\urllib3\util\wait.py", line 1, in &lt;module&gt;
    from .selectors import (
  File "C:\Users\piyat\AppData\Local\Packages\PythonSoftwareFoundation.Python.3.10_qbz5n2kfra8p0\LocalCache\local-packages\Python310\site-packages\urllib3\util\selectors.py", line 14, in &lt;module&gt;
    from collections import namedtuple, Mapping
PYTHONPATH:
  C:\Users\piyat\source\repos\Demo_API_AutomationTest_RobotFramwork
  C:\Program Files\WindowsApps\PythonSoftwareFoundation.Python.3.10_3.10.3056.0_x64__qbz5n2kfra8p0\python310.zip
  C:\Program Files\WindowsApps\PythonSoftwareFoundation.Python.3.10_3.10.3056.0_x64__qbz5n2kfra8p0\DLLs
  C:\Program Files\WindowsApps\PythonSoftwareFoundation.Python.3.10_3.10.3056.0_x64__qbz5n2kfra8p0\lib
  C:\Users\piyat\AppData\Local\Microsoft\WindowsApps\PythonSoftwareFoundation.Python.3.10_qbz5n2kfra8p0
  C:\Users\piyat\AppData\Local\Packages\PythonSoftwareFoundation.Python.3.10_qbz5n2kfra8p0\LocalCache\local-packages\Python310\site-packages
  C:\Program Files\WindowsApps\PythonSoftwareFoundation.Python.3.10_3.10.3056.0_x64__qbz5n2kfra8p0
  C:\Program Files\WindowsApps\PythonSoftwareFoundation.Python.3.10_3.10.3056.0_x64__qbz5n2kfra8p0\lib\site-packages</msg>
<msg timestamp="20230806 21:12:08.941" level="ERROR">Error in file 'C:\Users\piyat\source\repos\Demo_API_AutomationTest_RobotFramwork\imports\library.robot' on line 5: Importing library 'RequestsLibrary' failed: ImportError: cannot import name 'Mapping' from 'collections' (C:\Program Files\WindowsApps\PythonSoftwareFoundation.Python.3.10_3.10.3056.0_x64__qbz5n2kfra8p0\lib\collections\__init__.py)
Traceback (most recent call last):
  File "C:\Users\piyat\AppData\Local\Packages\PythonSoftwareFoundation.Python.3.10_qbz5n2kfra8p0\LocalCache\local-packages\Python310\site-packages\RequestsLibrary\__init__.py", line 1, in &lt;module&gt;
    from .DeprecatedKeywords import DeprecatedKeywords
  File "C:\Users\piyat\AppData\Local\Packages\PythonSoftwareFoundation.Python.3.10_qbz5n2kfra8p0\LocalCache\local-packages\Python310\site-packages\RequestsLibrary\DeprecatedKeywords.py", line 6, in &lt;module&gt;
    from RequestsLibrary import utils
  File "C:\Users\piyat\AppData\Local\Packages\PythonSoftwareFoundation.Python.3.10_qbz5n2kfra8p0\LocalCache\local-packages\Python310\site-packages\RequestsLibrary\utils.py", line 5, in &lt;module&gt;
    from requests.status_codes import codes
  File "C:\Users\piyat\AppData\Local\Packages\PythonSoftwareFoundation.Python.3.10_qbz5n2kfra8p0\LocalCache\local-packages\Python310\site-packages\requests\__init__.py", line 43, in &lt;module&gt;
    import urllib3
  File "C:\Users\piyat\AppData\Local\Packages\PythonSoftwareFoundation.Python.3.10_qbz5n2kfra8p0\LocalCache\local-packages\Python310\site-packages\urllib3\__init__.py", line 8, in &lt;module&gt;
    from .connectionpool import (
  File "C:\Users\piyat\AppData\Local\Packages\PythonSoftwareFoundation.Python.3.10_qbz5n2kfra8p0\LocalCache\local-packages\Python310\site-packages\urllib3\connectionpool.py", line 29, in &lt;module&gt;
    from .connection import (
  File "C:\Users\piyat\AppData\Local\Packages\PythonSoftwareFoundation.Python.3.10_qbz5n2kfra8p0\LocalCache\local-packages\Python310\site-packages\urllib3\connection.py", line 39, in &lt;module&gt;
    from .util.ssl_ import (
  File "C:\Users\piyat\AppData\Local\Packages\PythonSoftwareFoundation.Python.3.10_qbz5n2kfra8p0\LocalCache\local-packages\Python310\site-packages\urllib3\util\__init__.py", line 3, in &lt;module&gt;
    from .connection import is_connection_dropped
  File "C:\Users\piyat\AppData\Local\Packages\PythonSoftwareFoundation.Python.3.10_qbz5n2kfra8p0\LocalCache\local-packages\Python310\site-packages\urllib3\util\connection.py", line 3, in &lt;module&gt;
    from .wait import wait_for_read
  File "C:\Users\piyat\AppData\Local\Packages\PythonSoftwareFoundation.Python.3.10_qbz5n2kfra8p0\LocalCache\local-packages\Python310\site-packages\urllib3\util\wait.py", line 1, in &lt;module&gt;
    from .selectors import (
  File "C:\Users\piyat\AppData\Local\Packages\PythonSoftwareFoundation.Python.3.10_qbz5n2kfra8p0\LocalCache\local-packages\Python310\site-packages\urllib3\util\selectors.py", line 14, in &lt;module&gt;
    from collections import namedtuple, Mapping
PYTHONPATH:
  C:\Users\piyat\source\repos\Demo_API_AutomationTest_RobotFramwork
  C:\Program Files\WindowsApps\PythonSoftwareFoundation.Python.3.10_3.10.3056.0_x64__qbz5n2kfra8p0\python310.zip
  C:\Program Files\WindowsApps\PythonSoftwareFoundation.Python.3.10_3.10.3056.0_x64__qbz5n2kfra8p0\DLLs
  C:\Program Files\WindowsApps\PythonSoftwareFoundation.Python.3.10_3.10.3056.0_x64__qbz5n2kfra8p0\lib
  C:\Users\piyat\AppData\Local\Microsoft\WindowsApps\PythonSoftwareFoundation.Python.3.10_qbz5n2kfra8p0
  C:\Users\piyat\AppData\Local\Packages\PythonSoftwareFoundation.Python.3.10_qbz5n2kfra8p0\LocalCache\local-packages\Python310\site-packages
  C:\Program Files\WindowsApps\PythonSoftwareFoundation.Python.3.10_3.10.3056.0_x64__qbz5n2kfra8p0
  C:\Program Files\WindowsApps\PythonSoftwareFoundation.Python.3.10_3.10.3056.0_x64__qbz5n2kfra8p0\lib\site-packages</msg>
<msg timestamp="20230806 21:12:08.957" level="ERROR">Error in file 'C:\Users\piyat\source\repos\Demo_API_AutomationTest_RobotFramwork\imports\library.robot' on line 7: Importing library 'REST' failed: ImportError: cannot import name 'Mapping' from 'collections' (C:\Program Files\WindowsApps\PythonSoftwareFoundation.Python.3.10_3.10.3056.0_x64__qbz5n2kfra8p0\lib\collections\__init__.py)
Traceback (most recent call last):
  File "C:\Users\piyat\AppData\Local\Packages\PythonSoftwareFoundation.Python.3.10_qbz5n2kfra8p0\LocalCache\local-packages\Python310\site-packages\REST\__init__.py", line 28, in &lt;module&gt;
    from requests.packages.urllib3 import disable_warnings
  File "C:\Users\piyat\AppData\Local\Packages\PythonSoftwareFoundation.Python.3.10_qbz5n2kfra8p0\LocalCache\local-packages\Python310\site-packages\requests\__init__.py", line 43, in &lt;module&gt;
    import urllib3
  File "C:\Users\piyat\AppData\Local\Packages\PythonSoftwareFoundation.Python.3.10_qbz5n2kfra8p0\LocalCache\local-packages\Python310\site-packages\urllib3\__init__.py", line 8, in &lt;module&gt;
    from .connectionpool import (
  File "C:\Users\piyat\AppData\Local\Packages\PythonSoftwareFoundation.Python.3.10_qbz5n2kfra8p0\LocalCache\local-packages\Python310\site-packages\urllib3\connectionpool.py", line 29, in &lt;module&gt;
    from .connection import (
  File "C:\Users\piyat\AppData\Local\Packages\PythonSoftwareFoundation.Python.3.10_qbz5n2kfra8p0\LocalCache\local-packages\Python310\site-packages\urllib3\connection.py", line 39, in &lt;module&gt;
    from .util.ssl_ import (
  File "C:\Users\piyat\AppData\Local\Packages\PythonSoftwareFoundation.Python.3.10_qbz5n2kfra8p0\LocalCache\local-packages\Python310\site-packages\urllib3\util\__init__.py", line 3, in &lt;module&gt;
    from .connection import is_connection_dropped
  File "C:\Users\piyat\AppData\Local\Packages\PythonSoftwareFoundation.Python.3.10_qbz5n2kfra8p0\LocalCache\local-packages\Python310\site-packages\urllib3\util\connection.py", line 3, in &lt;module&gt;
    from .wait import wait_for_read
  File "C:\Users\piyat\AppData\Local\Packages\PythonSoftwareFoundation.Python.3.10_qbz5n2kfra8p0\LocalCache\local-packages\Python310\site-packages\urllib3\util\wait.py", line 1, in &lt;module&gt;
    from .selectors import (
  File "C:\Users\piyat\AppData\Local\Packages\PythonSoftwareFoundation.Python.3.10_qbz5n2kfra8p0\LocalCache\local-packages\Python310\site-packages\urllib3\util\selectors.py", line 14, in &lt;module&gt;
    from collections import namedtuple, Mapping
PYTHONPATH:
  C:\Users\piyat\source\repos\Demo_API_AutomationTest_RobotFramwork
  C:\Program Files\WindowsApps\PythonSoftwareFoundation.Python.3.10_3.10.3056.0_x64__qbz5n2kfra8p0\python310.zip
  C:\Program Files\WindowsApps\PythonSoftwareFoundation.Python.3.10_3.10.3056.0_x64__qbz5n2kfra8p0\DLLs
  C:\Program Files\WindowsApps\PythonSoftwareFoundation.Python.3.10_3.10.3056.0_x64__qbz5n2kfra8p0\lib
  C:\Users\piyat\AppData\Local\Microsoft\WindowsApps\PythonSoftwareFoundation.Python.3.10_qbz5n2kfra8p0
  C:\Users\piyat\AppData\Local\Packages\PythonSoftwareFoundation.Python.3.10_qbz5n2kfra8p0\LocalCache\local-packages\Python310\site-packages
  C:\Program Files\WindowsApps\PythonSoftwareFoundation.Python.3.10_3.10.3056.0_x64__qbz5n2kfra8p0
  C:\Program Files\WindowsApps\PythonSoftwareFoundation.Python.3.10_3.10.3056.0_x64__qbz5n2kfra8p0\lib\site-packages</msg>
<msg timestamp="20230806 21:12:08.973" level="ERROR">Error in file 'C:\Users\piyat\source\repos\Demo_API_AutomationTest_RobotFramwork\imports\library.robot' on line 8: Importing library 'SeleniumLibrary' failed: ImportError: cannot import name 'Mapping' from 'collections' (C:\Program Files\WindowsApps\PythonSoftwareFoundation.Python.3.10_3.10.3056.0_x64__qbz5n2kfra8p0\lib\collections\__init__.py)
Traceback (most recent call last):
  File "C:\Users\piyat\AppData\Local\Packages\PythonSoftwareFoundation.Python.3.10_qbz5n2kfra8p0\LocalCache\local-packages\Python310\site-packages\SeleniumLibrary\__init__.py", line 28, in &lt;module&gt;
    from selenium.webdriver.remote.webdriver import WebDriver
  File "C:\Users\piyat\AppData\Local\Packages\PythonSoftwareFoundation.Python.3.10_qbz5n2kfra8p0\LocalCache\local-packages\Python310\site-packages\selenium\webdriver\remote\webdriver.py", line 27, in &lt;module&gt;
    from .remote_connection import RemoteConnection
  File "C:\Users\piyat\AppData\Local\Packages\PythonSoftwareFoundation.Python.3.10_qbz5n2kfra8p0\LocalCache\local-packages\Python310\site-packages\selenium\webdriver\remote\remote_connection.py", line 24, in &lt;module&gt;
    import urllib3
  File "C:\Users\piyat\AppData\Local\Packages\PythonSoftwareFoundation.Python.3.10_qbz5n2kfra8p0\LocalCache\local-packages\Python310\site-packages\urllib3\__init__.py", line 8, in &lt;module&gt;
    from .connectionpool import (
  File "C:\Users\piyat\AppData\Local\Packages\PythonSoftwareFoundation.Python.3.10_qbz5n2kfra8p0\LocalCache\local-packages\Python310\site-packages\urllib3\connectionpool.py", line 29, in &lt;module&gt;
    from .connection import (
  File "C:\Users\piyat\AppData\Local\Packages\PythonSoftwareFoundation.Python.3.10_qbz5n2kfra8p0\LocalCache\local-packages\Python310\site-packages\urllib3\connection.py", line 39, in &lt;module&gt;
    from .util.ssl_ import (
  File "C:\Users\piyat\AppData\Local\Packages\PythonSoftwareFoundation.Python.3.10_qbz5n2kfra8p0\LocalCache\local-packages\Python310\site-packages\urllib3\util\__init__.py", line 3, in &lt;module&gt;
    from .connection import is_connection_dropped
  File "C:\Users\piyat\AppData\Local\Packages\PythonSoftwareFoundation.Python.3.10_qbz5n2kfra8p0\LocalCache\local-packages\Python310\site-packages\urllib3\util\connection.py", line 3, in &lt;module&gt;
    from .wait import wait_for_read
  File "C:\Users\piyat\AppData\Local\Packages\PythonSoftwareFoundation.Python.3.10_qbz5n2kfra8p0\LocalCache\local-packages\Python310\site-packages\urllib3\util\wait.py", line 1, in &lt;module&gt;
    from .selectors import (
  File "C:\Users\piyat\AppData\Local\Packages\PythonSoftwareFoundation.Python.3.10_qbz5n2kfra8p0\LocalCache\local-packages\Python310\site-packages\urllib3\util\selectors.py", line 14, in &lt;module&gt;
    from collections import namedtuple, Mapping
PYTHONPATH:
  C:\Users\piyat\source\repos\Demo_API_AutomationTest_RobotFramwork
  C:\Program Files\WindowsApps\PythonSoftwareFoundation.Python.3.10_3.10.3056.0_x64__qbz5n2kfra8p0\python310.zip
  C:\Program Files\WindowsApps\PythonSoftwareFoundation.Python.3.10_3.10.3056.0_x64__qbz5n2kfra8p0\DLLs
  C:\Program Files\WindowsApps\PythonSoftwareFoundation.Python.3.10_3.10.3056.0_x64__qbz5n2kfra8p0\lib
  C:\Users\piyat\AppData\Local\Microsoft\WindowsApps\PythonSoftwareFoundation.Python.3.10_qbz5n2kfra8p0
  C:\Users\piyat\AppData\Local\Packages\PythonSoftwareFoundation.Python.3.10_qbz5n2kfra8p0\LocalCache\local-packages\Python310\site-packages
  C:\Program Files\WindowsApps\PythonSoftwareFoundation.Python.3.10_3.10.3056.0_x64__qbz5n2kfra8p0
  C:\Program Files\WindowsApps\PythonSoftwareFoundation.Python.3.10_3.10.3056.0_x64__qbz5n2kfra8p0\lib\site-packages</msg>
<msg timestamp="20230806 21:12:08.992" level="ERROR">Error in file 'C:\Users\piyat\source\repos\Demo_API_AutomationTest_RobotFramwork\imports\library.robot' on line 9: Importing library 'AppiumLibrary' failed: ImportError: cannot import name 'Mapping' from 'collections' (C:\Program Files\WindowsApps\PythonSoftwareFoundation.Python.3.10_3.10.3056.0_x64__qbz5n2kfra8p0\lib\collections\__init__.py)
Traceback (most recent call last):
  File "C:\Users\piyat\AppData\Local\Packages\PythonSoftwareFoundation.Python.3.10_qbz5n2kfra8p0\LocalCache\local-packages\Python310\site-packages\AppiumLibrary\__init__.py", line 4, in &lt;module&gt;
    from AppiumLibrary.keywords import *
  File "C:\Users\piyat\AppData\Local\Packages\PythonSoftwareFoundation.Python.3.10_qbz5n2kfra8p0\LocalCache\local-packages\Python310\site-packages\AppiumLibrary\keywords\__init__.py", line 7, in &lt;module&gt;
    from ._applicationmanagement import _ApplicationManagementKeywords
  File "C:\Users\piyat\AppData\Local\Packages\PythonSoftwareFoundation.Python.3.10_qbz5n2kfra8p0\LocalCache\local-packages\Python310\site-packages\AppiumLibrary\keywords\_applicationmanagement.py", line 6, in &lt;module&gt;
    from appium import webdriver
  File "C:\Users\piyat\AppData\Local\Packages\PythonSoftwareFoundation.Python.3.10_qbz5n2kfra8p0\LocalCache\local-packages\Python310\site-packages\appium\webdriver\__init__.py", line 19, in &lt;module&gt;
    from .webdriver import WebDriver as Remote
  File "C:\Users\piyat\AppData\Local\Packages\PythonSoftwareFoundation.Python.3.10_qbz5n2kfra8p0\LocalCache\local-packages\Python310\site-packages\appium\webdriver\webdriver.py", line 23, in &lt;module&gt;
    from selenium.webdriver.remote.remote_connection import RemoteConnection
  File "C:\Users\piyat\AppData\Local\Packages\PythonSoftwareFoundation.Python.3.10_qbz5n2kfra8p0\LocalCache\local-packages\Python310\site-packages\selenium\webdriver\remote\remote_connection.py", line 24, in &lt;module&gt;
    import urllib3
  File "C:\Users\piyat\AppData\Local\Packages\PythonSoftwareFoundation.Python.3.10_qbz5n2kfra8p0\LocalCache\local-packages\Python310\site-packages\urllib3\__init__.py", line 8, in &lt;module&gt;
    from .connectionpool import (
  File "C:\Users\piyat\AppData\Local\Packages\PythonSoftwareFoundation.Python.3.10_qbz5n2kfra8p0\LocalCache\local-packages\Python310\site-packages\urllib3\connectionpool.py", line 29, in &lt;module&gt;
    from .connection import (
  File "C:\Users\piyat\AppData\Local\Packages\PythonSoftwareFoundation.Python.3.10_qbz5n2kfra8p0\LocalCache\local-packages\Python310\site-packages\urllib3\connection.py", line 39, in &lt;module&gt;
    from .util.ssl_ import (
  File "C:\Users\piyat\AppData\Local\Packages\PythonSoftwareFoundation.Python.3.10_qbz5n2kfra8p0\LocalCache\local-packages\Python310\site-packages\urllib3\util\__init__.py", line 3, in &lt;module&gt;
    from .connection import is_connection_dropped
  File "C:\Users\piyat\AppData\Local\Packages\PythonSoftwareFoundation.Python.3.10_qbz5n2kfra8p0\LocalCache\local-packages\Python310\site-packages\urllib3\util\connection.py", line 3, in &lt;module&gt;
    from .wait import wait_for_read
  File "C:\Users\piyat\AppData\Local\Packages\PythonSoftwareFoundation.Python.3.10_qbz5n2kfra8p0\LocalCache\local-packages\Python310\site-packages\urllib3\util\wait.py", line 1, in &lt;module&gt;
    from .selectors import (
  File "C:\Users\piyat\AppData\Local\Packages\PythonSoftwareFoundation.Python.3.10_qbz5n2kfra8p0\LocalCache\local-packages\Python310\site-packages\urllib3\util\selectors.py", line 14, in &lt;module&gt;
    from collections import namedtuple, Mapping
PYTHONPATH:
  C:\Users\piyat\source\repos\Demo_API_AutomationTest_RobotFramwork
  C:\Program Files\WindowsApps\PythonSoftwareFoundation.Python.3.10_3.10.3056.0_x64__qbz5n2kfra8p0\python310.zip
  C:\Program Files\WindowsApps\PythonSoftwareFoundation.Python.3.10_3.10.3056.0_x64__qbz5n2kfra8p0\DLLs
  C:\Program Files\WindowsApps\PythonSoftwareFoundation.Python.3.10_3.10.3056.0_x64__qbz5n2kfra8p0\lib
  C:\Users\piyat\AppData\Local\Microsoft\WindowsApps\PythonSoftwareFoundation.Python.3.10_qbz5n2kfra8p0
  C:\Users\piyat\AppData\Local\Packages\PythonSoftwareFoundation.Python.3.10_qbz5n2kfra8p0\LocalCache\local-packages\Python310\site-packages
  C:\Program Files\WindowsApps\PythonSoftwareFoundation.Python.3.10_3.10.3056.0_x64__qbz5n2kfra8p0
  C:\Program Files\WindowsApps\PythonSoftwareFoundation.Python.3.10_3.10.3056.0_x64__qbz5n2kfra8p0\lib\site-packages</msg>
<msg timestamp="20230806 21:12:09.009" level="ERROR">Error in file 'C:\Users\piyat\source\repos\Demo_API_AutomationTest_RobotFramwork\imports\library.robot' on line 20: Importing library 'TestRail' failed: ModuleNotFoundError: No module named 'TestRail'
Traceback (most recent call last):
  None
PYTHONPATH:
  C:\Users\piyat\source\repos\Demo_API_AutomationTest_RobotFramwork
  C:\Program Files\WindowsApps\PythonSoftwareFoundation.Python.3.10_3.10.3056.0_x64__qbz5n2kfra8p0\python310.zip
  C:\Program Files\WindowsApps\PythonSoftwareFoundation.Python.3.10_3.10.3056.0_x64__qbz5n2kfra8p0\DLLs
  C:\Program Files\WindowsApps\PythonSoftwareFoundation.Python.3.10_3.10.3056.0_x64__qbz5n2kfra8p0\lib
  C:\Users\piyat\AppData\Local\Microsoft\WindowsApps\PythonSoftwareFoundation.Python.3.10_qbz5n2kfra8p0
  C:\Users\piyat\AppData\Local\Packages\PythonSoftwareFoundation.Python.3.10_qbz5n2kfra8p0\LocalCache\local-packages\Python310\site-packages
  C:\Program Files\WindowsApps\PythonSoftwareFoundation.Python.3.10_3.10.3056.0_x64__qbz5n2kfra8p0
  C:\Program Files\WindowsApps\PythonSoftwareFoundation.Python.3.10_3.10.3056.0_x64__qbz5n2kfra8p0\lib\site-packages</msg>
<msg timestamp="20230806 21:12:09.027" level="ERROR">Error in file 'C:\Users\piyat\source\repos\Demo_API_AutomationTest_RobotFramwork\keywords\endpoint\account_management.robot' on line 2: Importing library 'REST' failed: ImportError: cannot import name 'Mapping' from 'collections' (C:\Program Files\WindowsApps\PythonSoftwareFoundation.Python.3.10_3.10.3056.0_x64__qbz5n2kfra8p0\lib\collections\__init__.py)
Traceback (most recent call last):
  File "C:\Users\piyat\AppData\Local\Packages\PythonSoftwareFoundation.Python.3.10_qbz5n2kfra8p0\LocalCache\local-packages\Python310\site-packages\REST\__init__.py", line 28, in &lt;module&gt;
    from requests.packages.urllib3 import disable_warnings
  File "C:\Users\piyat\AppData\Local\Packages\PythonSoftwareFoundation.Python.3.10_qbz5n2kfra8p0\LocalCache\local-packages\Python310\site-packages\requests\__init__.py", line 43, in &lt;module&gt;
    import urllib3
  File "C:\Users\piyat\AppData\Local\Packages\PythonSoftwareFoundation.Python.3.10_qbz5n2kfra8p0\LocalCache\local-packages\Python310\site-packages\urllib3\__init__.py", line 8, in &lt;module&gt;
    from .connectionpool import (
  File "C:\Users\piyat\AppData\Local\Packages\PythonSoftwareFoundation.Python.3.10_qbz5n2kfra8p0\LocalCache\local-packages\Python310\site-packages\urllib3\connectionpool.py", line 29, in &lt;module&gt;
    from .connection import (
  File "C:\Users\piyat\AppData\Local\Packages\PythonSoftwareFoundation.Python.3.10_qbz5n2kfra8p0\LocalCache\local-packages\Python310\site-packages\urllib3\connection.py", line 39, in &lt;module&gt;
    from .util.ssl_ import (
  File "C:\Users\piyat\AppData\Local\Packages\PythonSoftwareFoundation.Python.3.10_qbz5n2kfra8p0\LocalCache\local-packages\Python310\site-packages\urllib3\util\__init__.py", line 3, in &lt;module&gt;
    from .connection import is_connection_dropped
  File "C:\Users\piyat\AppData\Local\Packages\PythonSoftwareFoundation.Python.3.10_qbz5n2kfra8p0\LocalCache\local-packages\Python310\site-packages\urllib3\util\connection.py", line 3, in &lt;module&gt;
    from .wait import wait_for_read
  File "C:\Users\piyat\AppData\Local\Packages\PythonSoftwareFoundation.Python.3.10_qbz5n2kfra8p0\LocalCache\local-packages\Python310\site-packages\urllib3\util\wait.py", line 1, in &lt;module&gt;
    from .selectors import (
  File "C:\Users\piyat\AppData\Local\Packages\PythonSoftwareFoundation.Python.3.10_qbz5n2kfra8p0\LocalCache\local-packages\Python310\site-packages\urllib3\util\selectors.py", line 14, in &lt;module&gt;
    from collections import namedtuple, Mapping
PYTHONPATH:
  C:\Users\piyat\source\repos\Demo_API_AutomationTest_RobotFramwork
  C:\Program Files\WindowsApps\PythonSoftwareFoundation.Python.3.10_3.10.3056.0_x64__qbz5n2kfra8p0\python310.zip
  C:\Program Files\WindowsApps\PythonSoftwareFoundation.Python.3.10_3.10.3056.0_x64__qbz5n2kfra8p0\DLLs
  C:\Program Files\WindowsApps\PythonSoftwareFoundation.Python.3.10_3.10.3056.0_x64__qbz5n2kfra8p0\lib
  C:\Users\piyat\AppData\Local\Microsoft\WindowsApps\PythonSoftwareFoundation.Python.3.10_qbz5n2kfra8p0
  C:\Users\piyat\AppData\Local\Packages\PythonSoftwareFoundation.Python.3.10_qbz5n2kfra8p0\LocalCache\local-packages\Python310\site-packages
  C:\Program Files\WindowsApps\PythonSoftwareFoundation.Python.3.10_3.10.3056.0_x64__qbz5n2kfra8p0
  C:\Program Files\WindowsApps\PythonSoftwareFoundation.Python.3.10_3.10.3056.0_x64__qbz5n2kfra8p0\lib\site-packages</msg>
</errors>
</robot>
