<?xml version="1.0" encoding="UTF-8"?>
<robot generator="Robot 4.1.1 (Python 3.10.11 on win32)" generated="20230802 21:36:53.370" rpa="false" schemaversion="2">
<suite id="s1" name="Functional Tests" source="C:\Users\piyat\source\repos\Demo_API_AutomationTest_RobotFramwork\testcases\functional_tests">
<suite id="s1-s1" name="Login" source="C:\Users\piyat\source\repos\Demo_API_AutomationTest_RobotFramwork\testcases\functional_tests\login.robot">
<test id="s1-s1-t1" name="Verify that users cann't login when email or password are incorrect via api">
<kw name="Set Test Variable" library="BuiltIn">
<arg>${email}</arg>
<arg>${authentication.email}</arg>
<doc>Makes a variable available everywhere within the scope of the current test.</doc>
<msg timestamp="20230802 21:36:53.710" level="INFO">${email} = eve.holt@reqres.in,</msg>
<status status="PASS" starttime="20230802 21:36:53.707" endtime="20230802 21:36:53.710"/>
</kw>
<kw name="Set Test Variable" library="BuiltIn">
<arg>${password}</arg>
<arg>${authentication.incorrect_password}</arg>
<doc>Makes a variable available everywhere within the scope of the current test.</doc>
<msg timestamp="20230802 21:36:53.713" level="INFO">${password} = test001,</msg>
<status status="PASS" starttime="20230802 21:36:53.712" endtime="20230802 21:36:53.714"/>
</kw>
<kw name="Verify customer login then status should be unauthorized" library="login">
<arg>${email}</arg>
<arg>${password}</arg>
<kw name="Customer login" library="account_management">
<var>${response}</var>
<arg>${email}</arg>
<arg>${password}</arg>
<arg>false</arg>
<doc>`is_jwt=true` will use with frontend only can't use on falcon api 
`is_jwt=false` will use with falcon api only can't use on frontend 
`is_jwt` should sent only string true or false. Not support ${TURE} or False</doc>
<kw name="Set Variable" library="BuiltIn">
<var>${username}</var>
<arg>${email}</arg>
<doc>Returns the given values which can then be assigned to a variables.</doc>
<msg timestamp="20230802 21:36:53.716" level="INFO">${username} = eve.holt@reqres.in,</msg>
<status status="PASS" starttime="20230802 21:36:53.716" endtime="20230802 21:36:53.716"/>
</kw>
<kw name="Set Variable" library="BuiltIn">
<var>${password}</var>
<arg>${password}</arg>
<doc>Returns the given values which can then be assigned to a variables.</doc>
<msg timestamp="20230802 21:36:53.717" level="INFO">${password} = test001,</msg>
<status status="PASS" starttime="20230802 21:36:53.717" endtime="20230802 21:36:53.717"/>
</kw>
<kw name="Set Variable" library="BuiltIn">
<var>${is_jwt}</var>
<arg>${is_jwt}</arg>
<doc>Returns the given values which can then be assigned to a variables.</doc>
<msg timestamp="20230802 21:36:53.717" level="INFO">${is_jwt} = false</msg>
<status status="PASS" starttime="20230802 21:36:53.717" endtime="20230802 21:36:53.717"/>
</kw>
<kw name="Set Variable" library="BuiltIn">
<var>${guest_token}</var>
<arg>${guest_token}</arg>
<doc>Returns the given values which can then be assigned to a variables.</doc>
<msg timestamp="20230802 21:36:53.718" level="INFO">${guest_token} = </msg>
<status status="PASS" starttime="20230802 21:36:53.717" endtime="20230802 21:36:53.718"/>
</kw>
<kw name="Get Templated Data From Path" library="TemplatedData">
<var>${request}</var>
<arg>C:\\Users\\piyat\\source\\repos\\Demo_API_AutomationTest_RobotFramwork\\keywords\\endpoint/account_managment/resources/login.json</arg>
<arg>return_type=json</arg>
<msg timestamp="20230802 21:36:53.718" level="INFO">${request} = {'email': 'eve.holt@reqres.in,', 'password': 'test001,'}</msg>
<status status="PASS" starttime="20230802 21:36:53.718" endtime="20230802 21:36:53.719"/>
</kw>
<kw name="Evaluate" library="BuiltIn">
<var>${body}</var>
<arg>json.dumps($request)</arg>
<arg>json</arg>
<doc>Evaluates the given expression in Python and returns the result.</doc>
<msg timestamp="20230802 21:36:53.730" level="INFO">${body} = {"email": "eve.holt@reqres.in,", "password": "test001,"}</msg>
<status status="PASS" starttime="20230802 21:36:53.719" endtime="20230802 21:36:53.730"/>
</kw>
<kw name="Post On Session">
<var>${response}=</var>
<arg>https://reqres.in/api/login</arg>
<arg>${body}</arg>
<msg timestamp="20230802 21:36:53.739" level="FAIL">No keyword with name 'Post On Session' found.</msg>
<status status="FAIL" starttime="20230802 21:36:53.739" endtime="20230802 21:36:53.739"/>
</kw>
<kw name="REST.Integer">
<arg>response status</arg>
<arg>200</arg>
<status status="NOT RUN" starttime="20230802 21:36:53.747" endtime="20230802 21:36:53.747"/>
</kw>
<kw name="REST.Output">
<var>${response}=</var>
<arg>response body</arg>
<status status="NOT RUN" starttime="20230802 21:36:53.750" endtime="20230802 21:36:53.750"/>
</kw>
<status status="FAIL" starttime="20230802 21:36:53.715" endtime="20230802 21:36:53.752"/>
</kw>
<kw name="Get Value From Json" library="JSONLibrary">
<var>${login_failed_status}</var>
<arg>${response}</arg>
<arg>$..errors[0].message</arg>
<doc>Get Value From JSON using JSONPath</doc>
<status status="NOT RUN" starttime="20230802 21:36:53.752" endtime="20230802 21:36:53.753"/>
</kw>
<kw name="Should Be Equal" library="BuiltIn">
<arg>${login_failed_status}[0]</arg>
<arg>Missing password</arg>
<doc>Fails if the given objects are unequal.</doc>
<status status="NOT RUN" starttime="20230802 21:36:53.753" endtime="20230802 21:36:53.753"/>
</kw>
<status status="FAIL" starttime="20230802 21:36:53.714" endtime="20230802 21:36:53.753"/>
</kw>
<tag>demo</tag>
<tag>regression</tag>
<status status="FAIL" starttime="20230802 21:36:53.706" endtime="20230802 21:36:53.754">No keyword with name 'Post On Session' found.</status>
</test>
<status status="FAIL" starttime="20230802 21:36:53.396" endtime="20230802 21:36:53.756"/>
</suite>
<status status="FAIL" starttime="20230802 21:36:53.372" endtime="20230802 21:36:53.759"/>
</suite>
<statistics>
<total>
<stat pass="0" fail="1" skip="0">All Tests</stat>
</total>
<tag>
<stat pass="0" fail="1" skip="0">demo</stat>
<stat pass="0" fail="1" skip="0">regression</stat>
</tag>
<suite>
<stat pass="0" fail="1" skip="0" id="s1" name="Functional Tests">Functional Tests</stat>
<stat pass="0" fail="1" skip="0" id="s1-s1" name="Login">Functional Tests.Login</stat>
</suite>
</statistics>
<errors>
<msg timestamp="20230802 21:36:53.432" level="ERROR">Error in file 'C:\Users\piyat\source\repos\Demo_API_AutomationTest_RobotFramwork\imports\library.robot' on line 5: Importing library 'RequestsLibrary' failed: ImportError: cannot import name 'Mapping' from 'collections' (C:\Program Files\WindowsApps\PythonSoftwareFoundation.Python.3.10_3.10.3056.0_x64__qbz5n2kfra8p0\lib\collections\__init__.py)
Traceback (most recent call last):
  File "C:\Users\piyat\AppData\Local\Packages\PythonSoftwareFoundation.Python.3.10_qbz5n2kfra8p0\LocalCache\local-packages\Python310\site-packages\RequestsLibrary\__init__.py", line 1, in &lt;module&gt;
    from .DeprecatedKeywords import DeprecatedKeywords
  File "C:\Users\piyat\AppData\Local\Packages\PythonSoftwareFoundation.Python.3.10_qbz5n2kfra8p0\LocalCache\local-packages\Python310\site-packages\RequestsLibrary\DeprecatedKeywords.py", line 6, in &lt;module&gt;
    from RequestsLibrary import utils
  File "C:\Users\piyat\AppData\Local\Packages\PythonSoftwareFoundation.Python.3.10_qbz5n2kfra8p0\LocalCache\local-packages\Python310\site-packages\RequestsLibrary\utils.py", line 5, in &lt;module&gt;
    from requests.status_codes import codes
  File "C:\Users\piyat\AppData\Local\Packages\PythonSoftwareFoundation.Python.3.10_qbz5n2kfra8p0\LocalCache\local-packages\Python310\site-packages\requests\__init__.py", line 43, in &lt;module&gt;
    import urllib3
  File "C:\Users\piyat\AppData\Local\Packages\PythonSoftwareFoundation.Python.3.10_qbz5n2kfra8p0\LocalCache\local-packages\Python310\site-packages\urllib3\__init__.py", line 8, in &lt;module&gt;
    from .connectionpool import (
  File "C:\Users\piyat\AppData\Local\Packages\PythonSoftwareFoundation.Python.3.10_qbz5n2kfra8p0\LocalCache\local-packages\Python310\site-packages\urllib3\connectionpool.py", line 29, in &lt;module&gt;
    from .connection import (
  File "C:\Users\piyat\AppData\Local\Packages\PythonSoftwareFoundation.Python.3.10_qbz5n2kfra8p0\LocalCache\local-packages\Python310\site-packages\urllib3\connection.py", line 39, in &lt;module&gt;
    from .util.ssl_ import (
  File "C:\Users\piyat\AppData\Local\Packages\PythonSoftwareFoundation.Python.3.10_qbz5n2kfra8p0\LocalCache\local-packages\Python310\site-packages\urllib3\util\__init__.py", line 3, in &lt;module&gt;
    from .connection import is_connection_dropped
  File "C:\Users\piyat\AppData\Local\Packages\PythonSoftwareFoundation.Python.3.10_qbz5n2kfra8p0\LocalCache\local-packages\Python310\site-packages\urllib3\util\connection.py", line 3, in &lt;module&gt;
    from .wait import wait_for_read
  File "C:\Users\piyat\AppData\Local\Packages\PythonSoftwareFoundation.Python.3.10_qbz5n2kfra8p0\LocalCache\local-packages\Python310\site-packages\urllib3\util\wait.py", line 1, in &lt;module&gt;
    from .selectors import (
  File "C:\Users\piyat\AppData\Local\Packages\PythonSoftwareFoundation.Python.3.10_qbz5n2kfra8p0\LocalCache\local-packages\Python310\site-packages\urllib3\util\selectors.py", line 14, in &lt;module&gt;
    from collections import namedtuple, Mapping
PYTHONPATH:
  C:\Users\piyat\source\repos\Demo_API_AutomationTest_RobotFramwork
  C:\Program Files\WindowsApps\PythonSoftwareFoundation.Python.3.10_3.10.3056.0_x64__qbz5n2kfra8p0\python310.zip
  C:\Program Files\WindowsApps\PythonSoftwareFoundation.Python.3.10_3.10.3056.0_x64__qbz5n2kfra8p0\DLLs
  C:\Program Files\WindowsApps\PythonSoftwareFoundation.Python.3.10_3.10.3056.0_x64__qbz5n2kfra8p0\lib
  C:\Users\piyat\AppData\Local\Microsoft\WindowsApps\PythonSoftwareFoundation.Python.3.10_qbz5n2kfra8p0
  C:\Users\piyat\AppData\Local\Packages\PythonSoftwareFoundation.Python.3.10_qbz5n2kfra8p0\LocalCache\local-packages\Python310\site-packages
  C:\Program Files\WindowsApps\PythonSoftwareFoundation.Python.3.10_3.10.3056.0_x64__qbz5n2kfra8p0
  C:\Program Files\WindowsApps\PythonSoftwareFoundation.Python.3.10_3.10.3056.0_x64__qbz5n2kfra8p0\lib\site-packages</msg>
<msg timestamp="20230802 21:36:53.485" level="ERROR">Error in file 'C:\Users\piyat\source\repos\Demo_API_AutomationTest_RobotFramwork\imports\library.robot' on line 7: Importing library 'REST' failed: ImportError: cannot import name 'Mapping' from 'collections' (C:\Program Files\WindowsApps\PythonSoftwareFoundation.Python.3.10_3.10.3056.0_x64__qbz5n2kfra8p0\lib\collections\__init__.py)
Traceback (most recent call last):
  File "C:\Users\piyat\AppData\Local\Packages\PythonSoftwareFoundation.Python.3.10_qbz5n2kfra8p0\LocalCache\local-packages\Python310\site-packages\REST\__init__.py", line 28, in &lt;module&gt;
    from requests.packages.urllib3 import disable_warnings
  File "C:\Users\piyat\AppData\Local\Packages\PythonSoftwareFoundation.Python.3.10_qbz5n2kfra8p0\LocalCache\local-packages\Python310\site-packages\requests\__init__.py", line 43, in &lt;module&gt;
    import urllib3
  File "C:\Users\piyat\AppData\Local\Packages\PythonSoftwareFoundation.Python.3.10_qbz5n2kfra8p0\LocalCache\local-packages\Python310\site-packages\urllib3\__init__.py", line 8, in &lt;module&gt;
    from .connectionpool import (
  File "C:\Users\piyat\AppData\Local\Packages\PythonSoftwareFoundation.Python.3.10_qbz5n2kfra8p0\LocalCache\local-packages\Python310\site-packages\urllib3\connectionpool.py", line 29, in &lt;module&gt;
    from .connection import (
  File "C:\Users\piyat\AppData\Local\Packages\PythonSoftwareFoundation.Python.3.10_qbz5n2kfra8p0\LocalCache\local-packages\Python310\site-packages\urllib3\connection.py", line 39, in &lt;module&gt;
    from .util.ssl_ import (
  File "C:\Users\piyat\AppData\Local\Packages\PythonSoftwareFoundation.Python.3.10_qbz5n2kfra8p0\LocalCache\local-packages\Python310\site-packages\urllib3\util\__init__.py", line 3, in &lt;module&gt;
    from .connection import is_connection_dropped
  File "C:\Users\piyat\AppData\Local\Packages\PythonSoftwareFoundation.Python.3.10_qbz5n2kfra8p0\LocalCache\local-packages\Python310\site-packages\urllib3\util\connection.py", line 3, in &lt;module&gt;
    from .wait import wait_for_read
  File "C:\Users\piyat\AppData\Local\Packages\PythonSoftwareFoundation.Python.3.10_qbz5n2kfra8p0\LocalCache\local-packages\Python310\site-packages\urllib3\util\wait.py", line 1, in &lt;module&gt;
    from .selectors import (
  File "C:\Users\piyat\AppData\Local\Packages\PythonSoftwareFoundation.Python.3.10_qbz5n2kfra8p0\LocalCache\local-packages\Python310\site-packages\urllib3\util\selectors.py", line 14, in &lt;module&gt;
    from collections import namedtuple, Mapping
PYTHONPATH:
  C:\Users\piyat\source\repos\Demo_API_AutomationTest_RobotFramwork
  C:\Program Files\WindowsApps\PythonSoftwareFoundation.Python.3.10_3.10.3056.0_x64__qbz5n2kfra8p0\python310.zip
  C:\Program Files\WindowsApps\PythonSoftwareFoundation.Python.3.10_3.10.3056.0_x64__qbz5n2kfra8p0\DLLs
  C:\Program Files\WindowsApps\PythonSoftwareFoundation.Python.3.10_3.10.3056.0_x64__qbz5n2kfra8p0\lib
  C:\Users\piyat\AppData\Local\Microsoft\WindowsApps\PythonSoftwareFoundation.Python.3.10_qbz5n2kfra8p0
  C:\Users\piyat\AppData\Local\Packages\PythonSoftwareFoundation.Python.3.10_qbz5n2kfra8p0\LocalCache\local-packages\Python310\site-packages
  C:\Program Files\WindowsApps\PythonSoftwareFoundation.Python.3.10_3.10.3056.0_x64__qbz5n2kfra8p0
  C:\Program Files\WindowsApps\PythonSoftwareFoundation.Python.3.10_3.10.3056.0_x64__qbz5n2kfra8p0\lib\site-packages</msg>
<msg timestamp="20230802 21:36:53.518" level="ERROR">Error in file 'C:\Users\piyat\source\repos\Demo_API_AutomationTest_RobotFramwork\imports\library.robot' on line 8: Importing library 'SeleniumLibrary' failed: ImportError: cannot import name 'Mapping' from 'collections' (C:\Program Files\WindowsApps\PythonSoftwareFoundation.Python.3.10_3.10.3056.0_x64__qbz5n2kfra8p0\lib\collections\__init__.py)
Traceback (most recent call last):
  File "C:\Users\piyat\AppData\Local\Packages\PythonSoftwareFoundation.Python.3.10_qbz5n2kfra8p0\LocalCache\local-packages\Python310\site-packages\SeleniumLibrary\__init__.py", line 28, in &lt;module&gt;
    from selenium.webdriver.remote.webdriver import WebDriver
  File "C:\Users\piyat\AppData\Local\Packages\PythonSoftwareFoundation.Python.3.10_qbz5n2kfra8p0\LocalCache\local-packages\Python310\site-packages\selenium\webdriver\__init__.py", line 18, in &lt;module&gt;
    from .firefox.webdriver import WebDriver as Firefox  # noqa
  File "C:\Users\piyat\AppData\Local\Packages\PythonSoftwareFoundation.Python.3.10_qbz5n2kfra8p0\LocalCache\local-packages\Python310\site-packages\selenium\webdriver\firefox\webdriver.py", line 29, in &lt;module&gt;
    from selenium.webdriver.remote.webdriver import WebDriver as RemoteWebDriver
  File "C:\Users\piyat\AppData\Local\Packages\PythonSoftwareFoundation.Python.3.10_qbz5n2kfra8p0\LocalCache\local-packages\Python310\site-packages\selenium\webdriver\remote\webdriver.py", line 27, in &lt;module&gt;
    from .remote_connection import RemoteConnection
  File "C:\Users\piyat\AppData\Local\Packages\PythonSoftwareFoundation.Python.3.10_qbz5n2kfra8p0\LocalCache\local-packages\Python310\site-packages\selenium\webdriver\remote\remote_connection.py", line 24, in &lt;module&gt;
    import urllib3
  File "C:\Users\piyat\AppData\Local\Packages\PythonSoftwareFoundation.Python.3.10_qbz5n2kfra8p0\LocalCache\local-packages\Python310\site-packages\urllib3\__init__.py", line 8, in &lt;module&gt;
    from .connectionpool import (
  File "C:\Users\piyat\AppData\Local\Packages\PythonSoftwareFoundation.Python.3.10_qbz5n2kfra8p0\LocalCache\local-packages\Python310\site-packages\urllib3\connectionpool.py", line 29, in &lt;module&gt;
    from .connection import (
  File "C:\Users\piyat\AppData\Local\Packages\PythonSoftwareFoundation.Python.3.10_qbz5n2kfra8p0\LocalCache\local-packages\Python310\site-packages\urllib3\connection.py", line 39, in &lt;module&gt;
    from .util.ssl_ import (
  File "C:\Users\piyat\AppData\Local\Packages\PythonSoftwareFoundation.Python.3.10_qbz5n2kfra8p0\LocalCache\local-packages\Python310\site-packages\urllib3\util\__init__.py", line 3, in &lt;module&gt;
    from .connection import is_connection_dropped
  File "C:\Users\piyat\AppData\Local\Packages\PythonSoftwareFoundation.Python.3.10_qbz5n2kfra8p0\LocalCache\local-packages\Python310\site-packages\urllib3\util\connection.py", line 3, in &lt;module&gt;
    from .wait import wait_for_read
  File "C:\Users\piyat\AppData\Local\Packages\PythonSoftwareFoundation.Python.3.10_qbz5n2kfra8p0\LocalCache\local-packages\Python310\site-packages\urllib3\util\wait.py", line 1, in &lt;module&gt;
    from .selectors import (
  File "C:\Users\piyat\AppData\Local\Packages\PythonSoftwareFoundation.Python.3.10_qbz5n2kfra8p0\LocalCache\local-packages\Python310\site-packages\urllib3\util\selectors.py", line 14, in &lt;module&gt;
    from collections import namedtuple, Mapping
PYTHONPATH:
  C:\Users\piyat\source\repos\Demo_API_AutomationTest_RobotFramwork
  C:\Program Files\WindowsApps\PythonSoftwareFoundation.Python.3.10_3.10.3056.0_x64__qbz5n2kfra8p0\python310.zip
  C:\Program Files\WindowsApps\PythonSoftwareFoundation.Python.3.10_3.10.3056.0_x64__qbz5n2kfra8p0\DLLs
  C:\Program Files\WindowsApps\PythonSoftwareFoundation.Python.3.10_3.10.3056.0_x64__qbz5n2kfra8p0\lib
  C:\Users\piyat\AppData\Local\Microsoft\WindowsApps\PythonSoftwareFoundation.Python.3.10_qbz5n2kfra8p0
  C:\Users\piyat\AppData\Local\Packages\PythonSoftwareFoundation.Python.3.10_qbz5n2kfra8p0\LocalCache\local-packages\Python310\site-packages
  C:\Program Files\WindowsApps\PythonSoftwareFoundation.Python.3.10_3.10.3056.0_x64__qbz5n2kfra8p0
  C:\Program Files\WindowsApps\PythonSoftwareFoundation.Python.3.10_3.10.3056.0_x64__qbz5n2kfra8p0\lib\site-packages</msg>
<msg timestamp="20230802 21:36:53.543" level="ERROR">Error in file 'C:\Users\piyat\source\repos\Demo_API_AutomationTest_RobotFramwork\imports\library.robot' on line 9: Importing library 'AppiumLibrary' failed: ImportError: cannot import name 'Mapping' from 'collections' (C:\Program Files\WindowsApps\PythonSoftwareFoundation.Python.3.10_3.10.3056.0_x64__qbz5n2kfra8p0\lib\collections\__init__.py)
Traceback (most recent call last):
  File "C:\Users\piyat\AppData\Local\Packages\PythonSoftwareFoundation.Python.3.10_qbz5n2kfra8p0\LocalCache\local-packages\Python310\site-packages\AppiumLibrary\__init__.py", line 4, in &lt;module&gt;
    from AppiumLibrary.keywords import *
  File "C:\Users\piyat\AppData\Local\Packages\PythonSoftwareFoundation.Python.3.10_qbz5n2kfra8p0\LocalCache\local-packages\Python310\site-packages\AppiumLibrary\keywords\__init__.py", line 7, in &lt;module&gt;
    from ._applicationmanagement import _ApplicationManagementKeywords
  File "C:\Users\piyat\AppData\Local\Packages\PythonSoftwareFoundation.Python.3.10_qbz5n2kfra8p0\LocalCache\local-packages\Python310\site-packages\AppiumLibrary\keywords\_applicationmanagement.py", line 6, in &lt;module&gt;
    from appium import webdriver
  File "C:\Users\piyat\AppData\Local\Packages\PythonSoftwareFoundation.Python.3.10_qbz5n2kfra8p0\LocalCache\local-packages\Python310\site-packages\appium\webdriver\__init__.py", line 19, in &lt;module&gt;
    from .webdriver import WebDriver as Remote
  File "C:\Users\piyat\AppData\Local\Packages\PythonSoftwareFoundation.Python.3.10_qbz5n2kfra8p0\LocalCache\local-packages\Python310\site-packages\appium\webdriver\webdriver.py", line 23, in &lt;module&gt;
    from selenium.webdriver.remote.remote_connection import RemoteConnection
  File "C:\Users\piyat\AppData\Local\Packages\PythonSoftwareFoundation.Python.3.10_qbz5n2kfra8p0\LocalCache\local-packages\Python310\site-packages\selenium\webdriver\remote\remote_connection.py", line 24, in &lt;module&gt;
    import urllib3
  File "C:\Users\piyat\AppData\Local\Packages\PythonSoftwareFoundation.Python.3.10_qbz5n2kfra8p0\LocalCache\local-packages\Python310\site-packages\urllib3\__init__.py", line 8, in &lt;module&gt;
    from .connectionpool import (
  File "C:\Users\piyat\AppData\Local\Packages\PythonSoftwareFoundation.Python.3.10_qbz5n2kfra8p0\LocalCache\local-packages\Python310\site-packages\urllib3\connectionpool.py", line 29, in &lt;module&gt;
    from .connection import (
  File "C:\Users\piyat\AppData\Local\Packages\PythonSoftwareFoundation.Python.3.10_qbz5n2kfra8p0\LocalCache\local-packages\Python310\site-packages\urllib3\connection.py", line 39, in &lt;module&gt;
    from .util.ssl_ import (
  File "C:\Users\piyat\AppData\Local\Packages\PythonSoftwareFoundation.Python.3.10_qbz5n2kfra8p0\LocalCache\local-packages\Python310\site-packages\urllib3\util\__init__.py", line 3, in &lt;module&gt;
    from .connection import is_connection_dropped
  File "C:\Users\piyat\AppData\Local\Packages\PythonSoftwareFoundation.Python.3.10_qbz5n2kfra8p0\LocalCache\local-packages\Python310\site-packages\urllib3\util\connection.py", line 3, in &lt;module&gt;
    from .wait import wait_for_read
  File "C:\Users\piyat\AppData\Local\Packages\PythonSoftwareFoundation.Python.3.10_qbz5n2kfra8p0\LocalCache\local-packages\Python310\site-packages\urllib3\util\wait.py", line 1, in &lt;module&gt;
    from .selectors import (
  File "C:\Users\piyat\AppData\Local\Packages\PythonSoftwareFoundation.Python.3.10_qbz5n2kfra8p0\LocalCache\local-packages\Python310\site-packages\urllib3\util\selectors.py", line 14, in &lt;module&gt;
    from collections import namedtuple, Mapping
PYTHONPATH:
  C:\Users\piyat\source\repos\Demo_API_AutomationTest_RobotFramwork
  C:\Program Files\WindowsApps\PythonSoftwareFoundation.Python.3.10_3.10.3056.0_x64__qbz5n2kfra8p0\python310.zip
  C:\Program Files\WindowsApps\PythonSoftwareFoundation.Python.3.10_3.10.3056.0_x64__qbz5n2kfra8p0\DLLs
  C:\Program Files\WindowsApps\PythonSoftwareFoundation.Python.3.10_3.10.3056.0_x64__qbz5n2kfra8p0\lib
  C:\Users\piyat\AppData\Local\Microsoft\WindowsApps\PythonSoftwareFoundation.Python.3.10_qbz5n2kfra8p0
  C:\Users\piyat\AppData\Local\Packages\PythonSoftwareFoundation.Python.3.10_qbz5n2kfra8p0\LocalCache\local-packages\Python310\site-packages
  C:\Program Files\WindowsApps\PythonSoftwareFoundation.Python.3.10_3.10.3056.0_x64__qbz5n2kfra8p0
  C:\Program Files\WindowsApps\PythonSoftwareFoundation.Python.3.10_3.10.3056.0_x64__qbz5n2kfra8p0\lib\site-packages</msg>
<msg timestamp="20230802 21:36:53.700" level="ERROR">Error in file 'C:\Users\piyat\source\repos\Demo_API_AutomationTest_RobotFramwork\keywords\endpoint\account_management.robot' on line 2: Importing library 'REST' failed: ImportError: cannot import name 'Mapping' from 'collections' (C:\Program Files\WindowsApps\PythonSoftwareFoundation.Python.3.10_3.10.3056.0_x64__qbz5n2kfra8p0\lib\collections\__init__.py)
Traceback (most recent call last):
  File "C:\Users\piyat\AppData\Local\Packages\PythonSoftwareFoundation.Python.3.10_qbz5n2kfra8p0\LocalCache\local-packages\Python310\site-packages\REST\__init__.py", line 28, in &lt;module&gt;
    from requests.packages.urllib3 import disable_warnings
  File "C:\Users\piyat\AppData\Local\Packages\PythonSoftwareFoundation.Python.3.10_qbz5n2kfra8p0\LocalCache\local-packages\Python310\site-packages\requests\__init__.py", line 43, in &lt;module&gt;
    import urllib3
  File "C:\Users\piyat\AppData\Local\Packages\PythonSoftwareFoundation.Python.3.10_qbz5n2kfra8p0\LocalCache\local-packages\Python310\site-packages\urllib3\__init__.py", line 8, in &lt;module&gt;
    from .connectionpool import (
  File "C:\Users\piyat\AppData\Local\Packages\PythonSoftwareFoundation.Python.3.10_qbz5n2kfra8p0\LocalCache\local-packages\Python310\site-packages\urllib3\connectionpool.py", line 29, in &lt;module&gt;
    from .connection import (
  File "C:\Users\piyat\AppData\Local\Packages\PythonSoftwareFoundation.Python.3.10_qbz5n2kfra8p0\LocalCache\local-packages\Python310\site-packages\urllib3\connection.py", line 39, in &lt;module&gt;
    from .util.ssl_ import (
  File "C:\Users\piyat\AppData\Local\Packages\PythonSoftwareFoundation.Python.3.10_qbz5n2kfra8p0\LocalCache\local-packages\Python310\site-packages\urllib3\util\__init__.py", line 3, in &lt;module&gt;
    from .connection import is_connection_dropped
  File "C:\Users\piyat\AppData\Local\Packages\PythonSoftwareFoundation.Python.3.10_qbz5n2kfra8p0\LocalCache\local-packages\Python310\site-packages\urllib3\util\connection.py", line 3, in &lt;module&gt;
    from .wait import wait_for_read
  File "C:\Users\piyat\AppData\Local\Packages\PythonSoftwareFoundation.Python.3.10_qbz5n2kfra8p0\LocalCache\local-packages\Python310\site-packages\urllib3\util\wait.py", line 1, in &lt;module&gt;
    from .selectors import (
  File "C:\Users\piyat\AppData\Local\Packages\PythonSoftwareFoundation.Python.3.10_qbz5n2kfra8p0\LocalCache\local-packages\Python310\site-packages\urllib3\util\selectors.py", line 14, in &lt;module&gt;
    from collections import namedtuple, Mapping
PYTHONPATH:
  C:\Users\piyat\source\repos\Demo_API_AutomationTest_RobotFramwork
  C:\Program Files\WindowsApps\PythonSoftwareFoundation.Python.3.10_3.10.3056.0_x64__qbz5n2kfra8p0\python310.zip
  C:\Program Files\WindowsApps\PythonSoftwareFoundation.Python.3.10_3.10.3056.0_x64__qbz5n2kfra8p0\DLLs
  C:\Program Files\WindowsApps\PythonSoftwareFoundation.Python.3.10_3.10.3056.0_x64__qbz5n2kfra8p0\lib
  C:\Users\piyat\AppData\Local\Microsoft\WindowsApps\PythonSoftwareFoundation.Python.3.10_qbz5n2kfra8p0
  C:\Users\piyat\AppData\Local\Packages\PythonSoftwareFoundation.Python.3.10_qbz5n2kfra8p0\LocalCache\local-packages\Python310\site-packages
  C:\Program Files\WindowsApps\PythonSoftwareFoundation.Python.3.10_3.10.3056.0_x64__qbz5n2kfra8p0
  C:\Program Files\WindowsApps\PythonSoftwareFoundation.Python.3.10_3.10.3056.0_x64__qbz5n2kfra8p0\lib\site-packages</msg>
</errors>
</robot>
